Workbook
Name ADaM或衍生数据集个数: 项目参数!$C$84
Name ClinicalTrials翻译YN: 服务费明细!$D$32
Name CMP撰写YN: 服务费明细!$D$72
Name CRA和中心的医学支持YN: 服务费明细!$D$100
Name CRA人数: 项目参数!$C$51
Name CRF唯一页面数: 项目参数!$C$66
Name CRF重复页面数: 项目参数!$C$67
Name CRF总页数_每例: 项目时间计划!$D$61
Name CSR月: 项目时间计划!$G$17
Name CSR撰写YN: 服务费明细!$D$222
Name Dry_Run_YN: 服务费明细!$D$156
Name Dry_Run次数: 项目参数!$C$95
Name DSMB_DMC_IDMC次数: 项目参数!$C$98
Name DSMB_DMC_IDMC统计TFLs_Dry_Run: 服务费明细!$D$167
Name DSMB_DMC_IDMC项目管理: 服务费明细!$D$170
Name DSMB重复TLFs数: 项目参数!#REF!
Name DSUR_TLFs数: 项目参数!#REF!
Name DSUR递交YN: 服务费明细!$D$215
Name DSUR翻译YN: 服务费明细!$D$214
Name DSUR数: 项目参数!$C$103
Name DSUR医学审核YN: 服务费明细!$D$110
Name DSUR撰写_中文YN: 服务费明细!$D$213
Name EDC: 项目参数!$C$65
Name EDC上线前测试YN: 服务费明细!$D$28
Name EDC数据列表审核YN: 服务费明细!$D$105
Name IB更新YN: 服务费明细!$D$221
Name ICSR报告处理YN: 服务费明细!$D$211
Name ICSR报告流程培训YN: 服务费明细!$D$210
Name IPMP审核YN: 服务费明细!$D$74
Name IRC稽查YN: 服务费明细!$D$245
Name IRC日常沟通YN: 服务费明细!$D$82
Name MMP撰写YN: 服务费明细!$D$98
Name MMR_TLFs数: 项目参数!#REF!
Name PD分析: 服务费明细!$D$185
Name PK分析: 服务费明细!$D$184
Name PK列表: 项目参数!$C$94
Name PMP撰写YN: 服务费明细!$D$71
Name Pop报告撰写YN: 服务费明细!$D$194
Name Pop计划撰写YN: 服务费明细!$D$191
Name Pop建模与模拟YN: 服务费明细!$D$193
Name Print_Area_1: 'Rate Card'!$B$29:$O$30
Name Print_Area_2: 'Rate Card'!$A$31:$L$54
Name Print_Area_3: 'Rate Card'!$B$31:$M$54
Name PV报告处理语言: 项目参数!$C$100
Name SAE报告医学审核YN: 服务费明细!$D$109
Name SAE发生率: 项目参数!$C$34
Name SAE个案描述撰写YN: 服务费明细!$D$224
Name SAE交叉报告一致性比对YN: 服务费明细!#REF!
Name SAE例次数: 项目参数!$C$102
Name SAE例数: 项目参数!$C$35
Name SAP_YN: 服务费明细!$D$144
Name SDTM数据集个数: 项目参数!$C$83
Name SDV比例: 项目参数!$C$50
Name SMO日常沟通YN: 服务费明细!$D$78
Name SMP撰写YN: 服务费明细!$D$205
Name SRC_SMC会TLFs数: 项目参数!#REF!
Name SRC_SMC章程撰写YN: 服务费明细!$D$42
Name SRC会议次数: 项目参数!$C$49
Name SRC形式: 服务费明细!$AI$43
Name SUSAR报告递交YN: 服务费明细!#REF!

Sheet 工具维护记录
A1: 序号 | B1: 日期 | C1: 维修点 | D1: 版本号
A2: 1 | B2: 45222 | C2: 更换代码规则 | D2: v3.01
A3: 2 | B3: 45225 | C3: 根据近期HV审阅情况，底表增加HV标准工时 | D3: v3.01
A4: 3 | B4: 45233 | C4: 《T0467 安全性数据库用户体验测试》PVS和PVP默认改为不激活 | D4: v3.01_20231103
A5: 4 | B5: 45237 | C5: Sheet《其他费用》差旅费次数公式微调;Sheet《项目参数》关闭期公式微调;Sheet《注册申报底表》AB列公式修正 | D5: v3.01_20231107
A6: 5 | B6: 45237 | C6: Sheet《项目时间计划》随访期仅描述做调整:项目时间计划拆治疗随访1/2/3,相加等于客户展示页的治疗随访期 | D6: v3.01_20231107
A7: 6 | B7: 45238 | C7: 1.Gateway 测试服务：0次。XML递交测试服务：1次。（这个基本是每个项目都可以这样报价。对于客户指定采用国际双语数据库时，可以增加Gateway测试的费用）2.安全性信号检测：0次。若客户没有明确需要信号检测的服务，以后均可以默认为0。 | D7: v3.01_20231108
A8: 7 | B8: 45253 | C8: 匹配《其他费用》科目，更新ERP导入表 | D8: v3.02_20231123
A9: 8 | B9: 45253 | C9: 与ZJW确认 《保险日常沟通》改为按次 | D9: v3.02_20231123
A10: 9 | B10: 45257 | C10: 根据D365建议，将注册中方案撰写命名和编码稍作调整，并同步至IT | D10: v3.02_20231127
A11: 10 | B11: 45257 | C11: 根据GPP要求，更新1）A092的DTA起草和审核(外部供应商各1份)，2) A092客户展示数量*外部供应商数； | D11: v3.02_20231127
A12: 11 | B12: 45261 | C12: A151 SAE个案描述撰写仅保留一行MM | D12: v3.02_20231201
A13: 12 | B13: 45267 | C13: 《其他费用明细》中差旅次数公式更新 | D13: v3.02_20231207
... A20: 19 | B20: 45341 | C20: Rate Card: 1) 更新2024年Rate Card。 2) 删除三个场景Rate，增加一个Rate系数调整，但须总经理审批方可使用。 3) 删除Rate Card中Rate Cost信息和毛利计算。原则上，商务运营不再支持毛利计算。合同完签后，由财务统一计算初始合同毛利和跟进实际毛利。 | D20: v3.05_20240219
C21: 2. LSA 改为 SA，LST改为ST。 ERP上线测试阶段将同步至D365
A22: 20 | B22: 45343 | C22: 修订SA和ST误操作的问题 | D22: v3.05_20240221
A23: 21 | B23: 45359 | C23: 修订PV A137备注，其他研究 改为 本研究 | D23: v3.05_20240308
A24: 22 | B24: 45461 | C24: 邵健：与工时系统保持一致，“中文名称项目经理修改为临床项目经理, 项目管理副总监 需要修改成临床项目总监” | D24: v3.06_20240618
A25: 23 | B25: 45461 | C25: 尝试增加场景，但由于缺少工时依据，后续待持续优化 | D25: v3.06_20240618
A26: 24 | B26: 45461 | C26: 增加DVP，SAP，SMP的PM审核，各1小时；增加IIT/非注册试验的卫健委备案 | D26: v3.06_20240618
A27: 25 | B27: 45483 | C27: 【服务费明细】 A136、A138和A139 单位调整为"报告版本"，A136增加备注“本项目ICSR报告为中文处理，若产生中英双语录入的报告，按照两个版本/报告计费；若有境外SUSAR报告，可按照1版本/报告计费”；【服务费底表】Q666~O678相应更新；【二三级标注】中二级任务单位调整。 | D27: v3.07_20240712
A28: 26 | B28: 45512 | C28: 【封面】加了韩博和姜总的信息，更新了BD信息，更新了公司地址 【项目时间计划】调整了条目的名称--“访视、差旅及报告小时” 【费用摘要】调整了税前金额格式，保留两位小数。 【服务费底表】调整了 T0331-SAP审核，PM审核的逻辑 【其他费用明细】 调整了格式、细节 | D28: v3.08_20240808
A29: 27 | B29: 45516 | C29: 【服务费明细】更新【D128】dry run的逻辑；【D30】【E30】遗传办变更次数和参数页link 【其他费用明细】hide部分组合；添加CRO间接费用、会务费与供应商费用激活的逻辑；快递费单价保留小数两位，牵头费单价公式调整（iferror a/b）；机构管理费呈现调整（加“”）。 | D29: v3.09_20240812
A30: 28 | B30: 45524 | C30: 【封面】BD信息更新 【其他费用明细】TM随机系统名称更变为 ：TrialMaster 随机发药系统 (RTSM Master) | D30: v3.10_20240820
A31: 29 | B31: 45588 | C31: 【封面】BD信息更新 地址更新 【服务费明细】及【其他费用明细】更新逻辑错误的地方 | D31: v3.11_20241023
A32: 30 | B32: 45611 | C32: 【封面】BD信息更新 logo 地址 | D32: v3.12_20241115
A33: 31 | B33: 45741 | C33: 【封面】BD信息更新 | D33: v3.15_20250325
... A42: 40 | B42: 46037 | C42: PV服务 【服务费明细】A143 DSUR翻译变更成DSUR撰写(英文) 删除A138、A139、A141 【服务费底表】删除T0465、T0466、T0481、T0482、T0484a 临床运营 【服务费明细】增加A243、A244、A245、A246、A247、A277、A278、A279。 删除A020、A021、A022、A023、A024 【服务费底表】增加T0703、T0704、T0705、T0706、T0707、T0708、T0709、T0710、T0711、T0712、T0713、T0714、T0793、T0794、T0795、T0796、T0797、T0798、T0799 删除T0048、T0049、T0050、T0051、T0052、T0053、T0054、T0055、T0056、T0057、T0058、T0059、T0060 医学 【服务费明细】增加A267、A150a、A151a、A001a、A267a 【服务费底表】增加T0775、T0776、T0777、TT0778、TT0779、TT0780 MS角色的任务删除 药理 【服务费明细】增加A270、A268、A269 【服务费底表】增加T0785、T0781、T0782、T0783、T0784、T0785 | D42: v4.0_20260119
C43: 数统 【服务费明细】增加A249、A250、A251、A252、A253、A254、A255、A256、A257、A258、A259、A260、A264、A265、A266、A271、A272、A273、A274、A275、A280、A281、A261、A262、A263 删除A085、A091、A097、A093、A098、A112、A228、A229、A230、A113 【服务费底表】增加T0712、T0713、T0714、T0715、T0716、T0717、T0718、T0719、T0720、T0721、T0722、T0723、T0724、T0725、T0726、T0727、T0728、T0730、T0731、T0732、T0734、T0735、T0736、T0737、T0738、T0739、T0740、T0742、T0743、T0744、T0745、T0746、T0747、T0748、T0749、T0750、T0751、T0752、T0753、T0763、T0764、T0765、T0766、T0767、T0768、T0770、T0771、T0772、T0773、T0774、T0786、T0787、T0788、T0789、T0790、T0741、T0791、T0792、T0754、T0755、T0756、T0757、T0758、T0759、T0760、T0761、T0762 删除T0195、T0196、T0197、T0198、T0199、T0200、T0201、T0611、T0612、T0613、T0246、T0247、T0248、T0249、T0250、T0615、T0616、T0773、T0774、T0258、T0259、T0260、T0261、T0262、T0273、T0274、T0276、T0277、T0278、T0279、T0619、T0280、T0281、T0282、T0283、T0365、T0366、T0367、T0368、T0369、T0370、T0624、T0625、T0626、T0671、T0672、T0673、T0674、T0675、T0676、T0677、T0678、T0371、T0372、T0373、T0374、T0375、T0376、T0627、T0628、T0629
A44: 41 | B44: 46097 | C44: 【服务费明细】新增 A284 A285 A286 A287 A288 | D44: v4.1_20260316
A45: 42 | B45: 46113 | C45: 【服务费明细】新增二级 A289 A290 A291 A292 A293 A294 A295 A296 A297 A298 A299 A300 A301 A302 A303 A304 A305 A306 A307 A308 A309 A310 A311 A312 A313 A314 A315 A316 A317 A318 A319 A320 A321 A322 A323 A324 A325 A326 A327 A328 A329 A330 A331 A332 A333 A334 A335 A336 A337 新增一级 I028 I029 I030 I031 I032 I033 I034 | D45: v4.2_20260401
A46: 43 | B46: 46149 | C46: 【服务费明细】新增二级 A338 【服务费底表】增加T0899 | D46: v4.21_20260507

Sheet 模板注意事项
A1: 模板注意事项 | O1: 报价参考
Q2: 闭口合同酌情
A3: 一、除管理层审阅外，sheet标签颜色为黑的须隐藏+锁定 | O3: 2级编码 | P3: 2级任务 | Q3: 参考
O4: A001 | P4: 方案撰写
A5: 二、角色ID不能重复，增加角色，请联系许小燕 | O5: A002 | P5: 撰写CRF
O6: A003 | P6: 方案版本更新
A7: 三、不用的行，列，sheet表： 不要删除，可以隐藏+锁定 | O7: A004 | P7: 主知情同意撰写
O8: A005 | P8: 主知情同意版本更新
A9: 四、任务编码不能手工修改，增减请联系报价同事 | O9: A006 | P9: 受试者日记卡撰写 | Q9: 健康人无
O10: A007 | P10: 受试者招募广告撰写
A11: 五、<ERP报价导入模板>M2 ,如有尾差，导入ERP前需要手动调入数量为1的任务中，并且增加底色方便知道改了哪里。 | O11: A008 | P11: 召开客户启动会
A12: *尾差定义是几分钱差异 | O12: A009 | P12: 方案培训
A13: *如果差异大于1角，则要检查哪里错了 | O13: A010 | P13: 中心可行性调研 | Q13: 单中心主知情即可,中心知情可不报
O14: A011 | P14: 筛选访视
O15: A012 | P15: 机构立项
O16: A013 | P16: 首次伦理文件准备和递交
O17: A014 | P17: 中心知情同意书撰写 | Q17: 单中心主知情即可,中心知情可不报
O18: A015 | P18: EDC上线前测试
O19: A016 | P19: 研究中心启动文件准备和快递
O20: A017 | P20: 临床试验国家局备案
O21: A018 | P21: 临床试验省局备案 | Q21: 单中心不报
O22: A019 | P22: ClinicalTrials翻译
O23: A020 | P23: 遗传办首次国际合作审批申报 | Q23: A020和A021二选一，可能是走正式流程也可能走备案即可
O24: A021 | P24: 遗传办国际合作备案申报 | Q24: A020和A021二选一，可能是走正式流程也可能走备案即可
O25: A022 | P25: 遗传办数据备份备案申报 | Q25: 仅相关探索适用
O26: A023 | P26: 遗传办变更申报 | Q26: 默认不报
O27: A024 | P27: 遗传办国际合作总结报告撰写
O28: A025 | P28: 召开方案讨论会 | Q28: 涉及启动前的方案变更或方案讨论需要和PI沟通的报上
O29: A026 | P29: 召开首次研究者会 | Q29: 单中心默认不报
O30: A027 | P30: SRC/SMC章程撰写
O31: A028 | P31: 召开SRC/SMC会
O32: A029 | P32: 召开中期研究者会 | Q32: 默认不报
O33: A030 | P33: 召开研究总结会 | Q33: 默认不报
O34: A031 | P34: 准备或签署研究中心合同
O35: A032 | P35: 启动访视
O36: A033 | P36: 启动访视_启动会的医学远程支持
O37: A034 | P37: 常规监查访视
O38: A035 | P38: 计划外访视
O39: A036 | P39: 协同访视
O40: A037 | P40: 远程访视/电话访视
...

Sheet 签批页
B2: 客户名称 | C2: =封面!$C$20 -> 0 | F2: 方案名称或项目简称 | G2: =封面!$C$12 -> 0
B3: 商机编号 | F3: 商机主题
B4: 业务类型 | F4: 是否已完成业务审阅
B5: 是否申请折扣 | C5: =IF(费用摘要!$D$25>0,"是","否") -> 否 | F5: 预期折扣比例 | G5: ="服务费"&费用摘要!$G$25&费用摘要!C27&费用摘要!G27 -> 服务费0有临系统0
B6: 其他描述 | F6: 客户交付版本号 | G6: =费用摘要!C2 -> 0
B7: 中心数/个 | C7: =启动中心数 -> 4 | F7: 入组受试者/例 | G7: =入组受试者数 -> 30
B8: 服务期/月 | C8: =项目参数!$C$37 -> 22.5 | F8: 入组期/月 | G8: =筛选月+入组月 -> 6
B9: 治疗随访/月 | C9: =治疗月+随访月+长随访月 -> 7 | F9: 启动和关闭/月 | G9: =项目参数!$C$41+项目参数!$C$44+项目参数!$C$45 -> 9
B10: 服务范围 | F10: 间接范围 | J10: 供应商
B11: 参数变化描述 | F11: 服务范围变化描述
B12: 附件
B13: 折扣前/含税 | C13: 总费用 | D13: =费用摘要!$D$38 -> 3727153.9 | F13: 服务费 | G13: =费用摘要!$D$24 -> 3569865.6
C14: 单例总费用 | D14: =IFERROR(D13/入组受试者数,0) -> 124238.46 | F14: 单例服务费 | G14: =IFERROR(G13/入组受试者数,0) -> 118995.52
B15: 类别(折扣后/含税) | C15: 单例总费用 | D15: 单例服务费 | E15: 总费用 | F15: 服务费 | G15: 有临系统费 | H15: 代垫费 (内部供应商+CRO间接费+会议费) | I15: 过手费 (外部供应商+中心)
B16: 当前版本 | C16: =IFERROR($E$16/入组受试者数,0) -> 124238.46 | D16: =IFERROR($F$16/入组受试者数,0) -> 118995.52 | E16: =费用摘要!$F$38 -> 3727153.9 | F16: =费用摘要!$F$24 -> 3569865.6 | G16: =费用摘要!$F$27*(1+费用摘要!C33) -> 0 | H16: =(其他费用明细!$I$28+其他费用明细!$I$33+其他费用明细!$I$35+其他费用明细!$I$19+其他费用明细!$I$7+其他费用明细!I45)*(1+其他费用明细!D73) -> 157288.3 | I16: =(其他费用明细!$I$46+SUM(,其他费用明细!I29:$I$30,其他费用明细!$I$34,其他费用明细!$I$36:$I$44))*(1+其他费用明细!$D$73) -> 0
B17: 差异 (更新版vs上一版) | C17: =C16-C18 -> 124238.46 | D17: =D16-D18 -> 118995.52 | E17: =E16-E18 -> 3727153.9 | F17: =F16-F18 -> 3569865.6 | G17: =G16-G18 -> 0 | H17: =H16-H18 -> 157288.3 | I17: =I16-I18 -> 0
B18: 上一版 | J18: 更新版本时,先复制数值此行数据
B20: 不含税 | I20: 含税 | J20: =费用摘要!$C$23 -> 0.066
B21: 业务 | C21: 小计 | D21: 折扣后小计 | E21: 占比 | F21: 单例小计 | G21: 单例折扣后小计 | I21: 业务 | J21: 小计 | K21: 折扣后小计 | L21: 占比 | M21: 单例小计 | N21: 单例折扣后小计
B22: 临床药理 | C22: =SUMIF(服务费底表!$H:$H,$B22,服务费底表!$AD:$AD)+SUMIF(注册申报底表!$G:$G,$B22,注册申报底表!$AA:$AA) -> 136995 | D22: =SUMIF(服务费底表!$H:$H,$B22,服务费底表!$AG:$AG)+SUMIF(注册申报底表!$G:$G,$B22,注册申报底表!$AD:$AD) -> 136995 | E22: =IFERROR(D22/$D$36,0) -> 0.040908171 | F22: =IFERROR($C22/入组受试者数,0) -> 4566.5 | G22: =IFERROR($D22/入组受试者数,0) -> 4566.5 | I22: 临床药理 | J22: =C22*(1+$J$20) -> 146036.67 | K22: =D22*(1+$J$20) -> 146036.67 | L22: =IFERROR(K22/$K$36,0) -> 0.040908171 | M22: =IFERROR($J22/入组受试者数,0) -> 4867.889 | N22: =IFERROR($K22/入组受试者数,0) -> 4867.889
B23: 临床运营 | C23: =SUMIF(服务费底表!$H:$H,$B23,服务费底表!$AD:$AD)+SUMIF(注册申报底表!$G:$G,$B23,注册申报底表!$AA:$AA) -> 1926585 | D23: =SUMIF(服务费底表!$H:$H,$B23,服务费底表!$AG:$AG)+SUMIF(注册申报底表!$G:$G,$B23,注册申报底表!$AD:$AD) -> 1926585 | E23: =IFERROR(D23/$D$36,0) -> 0.57529886 | F23: =IFERROR($C23/入组受试者数,0) -> 64219.5 | G23: =IFERROR($D23/入组受试者数,0) -> 64219.5 | I23: 临床运营 | J23: =C23*(1+$J$20) -> 2053739.6 | K23: =D23*(1+$J$20) -> 2053739.6 | L23: =IFERROR(K23/$K$36,0) -> 0.57529886 | M23: =IFERROR($J23/入组受试者数,0) -> 68457.987 | N23: =IFERROR($K23/入组受试者数,0) -> 68457.987
B24: 项目管理 | C24: =SUMIF(服务费底表!$S:$S,$B24,服务费底表!$AD:$AD)+SUMIF(注册申报底表!$R:$R,$B24,注册申报底表!$AA:$AA) -> 875135 | D24: =SUMIF(服务费底表!$S:$S,$B24,服务费底表!$AG:$AG)+SUMIF(注册申报底表!$R:$R,$B24,注册申报底表!$AD:$AD) -> 875135 | E24: =IFERROR(D24/$D$36,0) -> 0.26132466 | F24: =IFERROR($C24/入组受试者数,0) -> 29171.167 | G24: =IFERROR($D24/入组受试者数,0) -> 29171.167 | I24: 项目管理 | J24: =C24*(1+$J$20) -> 932893.91 | K24: =D24*(1+$J$20) -> 932893.91 | L24: =IFERROR(K24/$K$36,0) -> 0.26132466 | M24: =IFERROR($J24/入组受试者数,0) -> 31096.464 | N24: =IFERROR($K24/入组受试者数,0) -> 31096.464
B25: 临床监查 | C25: =SUMIF(服务费底表!$S:$S,$B25,服务费底表!$AD:$AD)+SUMIF(注册申报底表!$R:$R,$B25,注册申报底表!$AA:$AA) -> 1051450 | D25: =SUMIF(服务费底表!$S:$S,$B25,服务费底表!$AG:$AG)+SUMIF(注册申报底表!$R:$R,$B25,注册申报底表!$AD:$AD) -> 1051450 | E25: =IFERROR(D25/$D$36,0) -> 0.3139742 | F25: =IFERROR($C25/入组受试者数,0) -> 35048.333 | G25: =IFERROR($D25/入组受试者数,0) -> 35048.333 | I25: 临床监查 | J25: =C25*(1+$J$20) -> 1120845.7 | K25: =D25*(1+$J$20) -> 1120845.7 | L25: =IFERROR(K25/$K$36,0) -> 0.3139742 | M25: =IFERROR($J25/入组受试者数,0) -> 37361.523 | N25: =IFERROR($K25/入组受试者数,0) -> 37361.523
B26: 数统 | C26: =SUM(C27:C29) -> 457861.5 | D26: =SUM(D27:D29) -> 457861.5 | E26: =IFERROR(D26/$D$36,0) -> 0.13672234 | F26: =IFERROR($C26/入组受试者数,0) -> 15262.05 | G26: =IFERROR($D26/入组受试者数,0) -> 15262.05 | I26: 数统 | J26: =C26*(1+$J$20) -> 488080.36 | K26: =D26*(1+$J$20) -> 488080.36 | L26: =IFERROR(K26/$K$36,0) -> 0.13672234 | M26: =IFERROR($J26/入组受试者数,0) -> 16269.345 | N26: =IFERROR($K26/入组受试者数,0) -> 16269.345
B27: 数据管理 | C27: =SUMIF(服务费底表!$S:$S,$B27,服务费底表!$AD:$AD)+SUMIF(注册申报底表!$R:$R,$B27,注册申报底表!$AA:$AA) -> 193399 | D27: =SUMIF(服务费底表!$S:$S,$B27,服务费底表!$AG:$AG)+SUMIF(注册申报底表!$R:$R,$B27,注册申报底表!$AD:$AD) -> 193399 | E27: =IFERROR(D27/$D$36,0) -> 0.057751008 | F27: =IFERROR($C27/入组受试者数,0) -> 6446.6333 | G27: =IFERROR($D27/入组受试者数,0) -> 6446.6333 | I27: 数据管理 | J27: =C27*(1+$J$20) -> 206163.33 | K27: =D27*(1+$J$20) -> 206163.33 | L27: =IFERROR(K27/$K$36,0) -> 0.057751008 | M27: =IFERROR($J27/入组受试者数,0) -> 6872.1111 | N27: =IFERROR($K27/入组受试者数,0) -> 6872.1111
B28: 生物统计 | C28: =SUMIF(服务费底表!$S:$S,$B28,服务费底表!$AD:$AD)+SUMIF(注册申报底表!$R:$R,$B28,注册申报底表!$AA:$AA) -> 82100 | D28: =SUMIF(服务费底表!$S:$S,$B28,服务费底表!$AG:$AG)+SUMIF(注册申报底表!$R:$R,$B28,注册申报底表!$AD:$AD) -> 82100 | E28: =IFERROR(D28/$D$36,0) -> 0.024515937 | F28: =IFERROR($C28/入组受试者数,0) -> 2736.6667 | G28: =IFERROR($D28/入组受试者数,0) -> 2736.6667 | I28: 生物统计 | J28: =C28*(1+$J$20) -> 87518.6 | K28: =D28*(1+$J$20) -> 87518.6 | L28: =IFERROR(K28/$K$36,0) -> 0.024515937 | M28: =IFERROR($J28/入组受试者数,0) -> 2917.2867 | N28: =IFERROR($K28/入组受试者数,0) -> 2917.2867
B29: 统计分析 | C29: =SUMIF(服务费底表!$S:$S,$B29,服务费底表!$AD:$AD)+SUMIF(注册申报底表!$R:$R,$B29,注册申报底表!$AA:$AA) -> 182362.5 | D29: =SUMIF(服务费底表!$S:$S,$B29,服务费底表!$AG:$AG)+SUMIF(注册申报底表!$R:$R,$B29,注册申报底表!$AD:$AD) -> 182362.5 | E29: =IFERROR(D29/$D$36,0) -> 0.054455391 | F29: =IFERROR($C29/入组受试者数,0) -> 6078.75 | G29: =IFERROR($D29/入组受试者数,0) -> 6078.75 | I29: 统计分析 | J29: =C29*(1+$J$20) -> 194398.42 | K29: =D29*(1+$J$20) -> 194398.42 | L29: =IFERROR(K29/$K$36,0) -> 0.054455391 | M29: =IFERROR($J29/入组受试者数,0) -> 6479.9475 | N29: =IFERROR($K29/入组受试者数,0) -> 6479.9475
B30: 药物警戒 | C30: =SUMIF(服务费底表!$H:$H,$B30,服务费底表!$AD:$AD)+SUMIF(注册申报底表!$G:$G,$B30,注册申报底表!$AA:$AA) -> 175875 | D30: =SUMIF(服务费底表!$H:$H,$B30,服务费底表!$AG:$AG)+SUMIF(注册申报底表!$G:$G,$B30,注册申报底表!$AD:$AD) -> 175875 | E30: =IFERROR(D30/$D$36,0) -> 0.052518154 | F30: =IFERROR($C30/入组受试者数,0) -> 5862.5 | G30: =IFERROR($D30/入组受试者数,0) -> 5862.5 | I30: 药物警戒 | J30: =C30*(1+$J$20) -> 187482.75 | K30: =D30*(1+$J$20) -> 187482.75 | L30: =IFERROR(K30/$K$36,0) -> 0.052518154 | M30: =IFERROR($J30/入组受试者数,0) -> 6249.425 | N30: =IFERROR($K30/入组受试者数,0) -> 6249.425
B31: 医学 | C31: =SUMIF(服务费底表!$H:$H,$B31,服务费底表!$AD:$AD)+SUMIF(注册申报底表!$G:$G,$B31,注册申报底表!$AA:$AA) -> 651525.5 | D31: =SUMIF(服务费底表!$H:$H,$B31,服务费底表!$AG:$AG)+SUMIF(注册申报底表!$G:$G,$B31,注册申报底表!$AD:$AD) -> 651525.5 | E31: =IFERROR(D31/$D$36,0) -> 0.19455248 | F31: =IFERROR($C31/入组受试者数,0) -> 21717.517 | G31: =IFERROR($D31/入组受试者数,0) -> 21717.517 | I31: 医学 | J31: =C31*(1+$J$20) -> 694526.18 | K31: =D31*(1+$J$20) -> 694526.18 | L31: =IFERROR(K31/$K$36,0) -> 0.19455248 | M31: =IFERROR($J31/入组受试者数,0) -> 23150.873 | N31: =IFERROR($K31/入组受试者数,0) -> 23150.873
B32: 医学撰写 | C32: =SUMIF(服务费底表!$S:$S,$B32,服务费底表!$AD:$AD)+SUMIF(注册申报底表!$R:$R,$B32,注册申报底表!$AA:$AA) -> 238275 | D32: =SUMIF(服务费底表!$S:$S,$B32,服务费底表!$AG:$AG)+SUMIF(注册申报底表!$R:$R,$B32,注册申报底表!$AD:$AD) -> 238275 | E32: =IFERROR(D32/$D$36,0) -> 0.071151461 | F32: =IFERROR($C32/入组受试者数,0) -> 7942.5 | G32: =IFERROR($D32/入组受试者数,0) -> 7942.5 | I32: 医学撰写 | J32: =C32*(1+$J$20) -> 254001.15 | K32: =D32*(1+$J$20) -> 254001.15 | L32: =IFERROR(K32/$K$36,0) -> 0.071151461 | M32: =IFERROR($J32/入组受试者数,0) -> 8466.705 | N32: =IFERROR($K32/入组受试者数,0) -> 8466.705
B33: 医学监查 | C33: =SUMIF(服务费底表!$S:$S,$B33,服务费底表!$AD:$AD)+SUMIF(注册申报底表!$R:$R,$B33,注册申报底表!$AA:$AA) -> 413250.5 | D33: =SUMIF(服务费底表!$S:$S,$B33,服务费底表!$AG:$AG)+SUMIF(注册申报底表!$R:$R,$B33,注册申报底表!$AD:$AD) -> 413250.5 | E33: =IFERROR(D33/$D$36,0) -> 0.12340101 | F33: =IFERROR($C33/入组受试者数,0) -> 13775.017 | G33: =IFERROR($D33/入组受试者数,0) -> 13775.017 | I33: 医学监查 | J33: =C33*(1+$J$20) -> 440525.03 | K33: =D33*(1+$J$20) -> 440525.03 | L33: =IFERROR(K33/$K$36,0) -> 0.12340101 | M33: =IFERROR($J33/入组受试者数,0) -> 14684.168 | N33: =IFERROR($K33/入组受试者数,0) -> 14684.168
B34: 质量保证 | C34: =SUMIF(服务费底表!$H:$H,$B34,服务费底表!$AD:$AD)+SUMIF(注册申报底表!$G:$G,$B34,注册申报底表!$AA:$AA) -> 0 | D34: =SUMIF(服务费底表!$H:$H,$B34,服务费底表!$AG:$AG)+SUMIF(注册申报底表!$G:$G,$B34,注册申报底表!$AD:$AD) -> 0 | E34: =IFERROR(D34/$D$36,0) -> 0 | F34: =IFERROR($C34/入组受试者数,0) -> 0 | G34: =IFERROR($D34/入组受试者数,0) -> 0 | I34: 质量保证 | J34: =C34*(1+$J$20) -> 0 | K34: =D34*(1+$J$20) -> 0 | L34: =IFERROR(K34/$K$36,0) -> 0 | M34: =IFERROR($J34/入组受试者数,0) -> 0 | N34: =IFERROR($K34/入组受试者数,0) -> 0
B35: 注册 | C35: =SUMIF(注册申报底表!$G:$G,$B35,注册申报底表!$AA:$AA) -> 0 | D35: =SUMIF(服务费底表!$H:$H,$B35,服务费底表!$AG:$AG)+SUMIF(注册申报底表!$G:$G,$B35,注册申报底表!$AD:$AD) -> 0 | E35: =IFERROR(D35/$D$36,0) -> 0 | F35: =IFERROR($C35/入组受试者数,0) -> 0 | G35: =IFERROR($D35/入组受试者数,0) -> 0 | I35: 注册 | J35: =C35*(1+$J$20) -> 0 | K35: =D35*(1+$J$20) -> 0 | L35: =IFERROR(K35/$K$36,0) -> 0 | M35: =IFERROR($J35/入组受试者数,0) -> 0 | N35: =IFERROR($K35/入组受试者数,0) -> 0
B36: 服务费 | C36: =SUM(C22:C23,C27:C31,C34:C35) -> 3348842 | D36: =SUM(D22:D23,D27:D31,D34:D35) -> 3348842 | E36: =SUM(E22:E23,E27:E31,E34:E35) -> 1 | F36: =SUM(F22:F23,F27:F31,F34:F35) -> 111628.07 | G36: =SUM(G22:G23,G27:G31,G34:G35) -> 111628.07 | I36: 服务费 | J36: =SUM(J22:J23,J27:J31,J34:J35) -> 3569865.6 | K36: =SUM(K22:K23,K27:K31,K34:K35) -> 3569865.6 | L36: =SUM(L22:L23,L27:L31,L34:L35) -> 1 | M36: =SUM(M22:M23,M27:M31,M34:M35) -> 118995.52 | N36: =SUM(N22:N23,N27:N31,N34:N35) -> 118995.52
B38: 服务费含税 | C38: =C36*(1+服务费明细!$C$252) -> 3569865.6 | D38: =D36*(1+服务费明细!$C$252) -> 3569865.6 | F38: =F36*(1+服务费明细!$C$252) -> 118995.52 | G38: =G36*(1+服务费明细!$C$252) -> 118995.52 | I38: 服务费含税Check | J38: =J36-C38 -> 0 | K38: =K36-D38 -> 0 | M38: =M36-F38 -> 0 | N38: =N36-G38 -> 0
B39: 其他费用含税 | C39: =费用摘要!D34 -> 157288.3 | D39: =费用摘要!F34 -> 157288.3 | F39: =IFERROR(C39/入组受试者数,0) -> 5242.9433 | G39: =IFERROR(D39/入组受试者数,0) -> 5242.9433
B40: 总计含税 | C40: =C38+C39 -> 3727153.9 | D40: =D38+D39 -> 3727153.9 | F40: =F38+F39 -> 124238.46 | G40: =G38+G39 -> 124238.46
B42: 服务费含税Check | C42: =C38-G13 -> 0.0020000003 | D42: =D38-F16 -> 0.0020000003 | F42: =F38-G14 -> 6.6666675e-05 | G42: =G38-D16 -> 6.6666675e-05
B43: 其他费用含税Check | C43: =C39-(D13-G13) -> 0 | D43: =D39-SUM(G16:I16) -> 0 | F43: =F39-(D14-G14) -> 1.8189894e-11 | G43: =G39-(C16-D16) -> 1.8189894e-11
B50: 名称-CN | C50: 部门名称-EN | D50: 业务属性 | E50: 报价岗位_通用名 | F50: 报价岗位_EN Abbr. | G50: 报价总工时
...

Sheet Rebid记录
A2: 商机编号 | C2: 有临CRM系统形成的商机编号
G3: 含税
A4: 交付版本号 | B4: PM | C4: 报价人员 | D4: 交付日期 | E4: 参数变化 | F4: 服务范围变化 | G4: 合同额 | H4: 服务费 | I4: 其他费用 | J4: TrialMaster系统 | K4: CRO间接费用 | L4: 会议相关费用 | M4: 供应商费用 | N4: 研究中心费用 | O4: 辅助文件 (截图等)
A5: v1 | G5: =SUM(H5:N5) -> 0
A6: v2 | G6: =SUM(H6:N6) -> 0
A7: v3 | G7: =SUM(H7:N7) -> 0
A8: v4 | G8: =SUM(H8:N8) -> 0
A9: v5 | G9: =SUM(H9:N9) -> 0
A10: v6 | G10: =SUM(H10:N10) -> 0
A11: v7 | G11: =SUM(H11:N11) -> 0
A12: v8 | G12: =SUM(H12:N12) -> 0

Sheet 合同变更记录
A1: 项目编号 | C1: 有临项目立项和交接流程形成的项目编号
E2: 含税
A3: 合同类型 | B3: PM | C3: 报价人员 | D3: 签署日期 (年月日) | E3: 合同额 | F3: 服务费 | G3: 其他费用 | H3: 参数变更 | I3: 服务范围变更 | J3: 合同编号 | K3: 辅助文件 (截图等)
A4: 初始合同 | E4: =F4+G4 -> 0 | H4: NA | I4: NA
E5: =F5+G5 -> 0
E6: =F6+G6 -> 0
E7: =F7+G7 -> 0
E8: =F8+G8 -> 0
E9: =F9+G9 -> 0
E10: =F10+G10 -> 0
E11: =F11+G11 -> 0
E12: =F12+G12 -> 0
E13: =F13+G13 -> 0
D17: 截止当前本项目费用 | E17: =SUM(E4:E13) -> 0 | F17: =SUM(F4:F13) -> 0 | G17: =SUM(G4:G13) -> 0

Sheet 封面
B7: 临床试验服务预算计划书
B12: 方案或项目名称:
B18: 提供给
B20: 客户：
B25: 提供方： | C25: 上海有临医药科技有限公司(简称"有临")
B27: 地址： | C27: 上海市浦东新区育仁路188弄1号楼10楼（科学之门T2）
B29: 联系人: | F29: 姓名 | G29: 电话 | H29: 邮箱
F30: 谭玉怡 | G30: 15626128895 | H30: tanyy@unionclin.com
B31: 邮箱: | C31: =IF($C$29="","",INDEX($H:$H,MATCH($C$29,$F:$F,0))) | F31: 王伟彪 | G31: 15232100683 | H31: wangwb@unionclin.com
F32: 李乔 | G32: 18851700778 | H32: liq@unionclin.com
B33: 电话: | C33: =IF($C$29="","",INDEX($G:$G,MATCH($C$29,$F:$F,0))) | F33: 史永健 | G33: 15800945389 | H33: shiyj@unionclin.com
F34: 姜岚 | G34: 13611830883 | H34: jiangl@unionclin.com
F35: 韩海雄 | G35: 13601749801 | H35: haixiong.han@unionclin.com
F36: 魏晓巍 | G36: 18510789550 | H36: weixw@unionclin.com
F37: 董剑峰 | G37: 18701581821 | H37: dongjf@unionclin.com
F38: 刘冬雪 | G38: 15244624058 | H38: liudx@unionclin.com
F39: 顾盼盼 | G39: 13675191158 | H39: gupp@unionclin.com
F40: 刘婷婷 | G40: 13882274379 | H40: liutt@unionclin.com
F41: 周艳 | G41: 13818233228 | H41: zhouy@unionclin.com
B43: 备注条款：
B44: 1. | C44: 临床试验服务预算仅作为正式合作协议/合同的附件内容，在双方开展正式合作之前，应签署连同本临床试验服务预算的正式协议/合同；
B45: 2. | C45: 鉴于客户项目任务的时间要求，有临同意在签署正式的合作协议之前，如客户出具先行同意本临床试验服务预算，有临在获得书面同意后可以先行开展工作；先行同意后，如客户出于策略考虑，项目提前结束，客户应支付有临已发生的的费用，包括服务费和实报费。 如先行同意，客户应签署以下签字页，盖章后将正式书面文件提交给有临。
B47: 是否先行同意：
B49: 客户签字及盖章：
B51: 日期：

Sheet 项目参数
A1: 报价场景(必选) | C1: 人员场景(必选) | D1: 商机编号(必填) | E1: Hide
A2: 注册肿瘤I/II期 | C2: 标准 | E2: Hide
E3: Hide
A4: 序号 | B4: 业务属性 | C4: 是否执行 | D4: 优惠率 | E4: Hide | F4: 不对外展示，内部说明
A5: 1 | B5: 医学撰写 | C5: 1 | E5: Hide
A6: 2 | B6: 医学监查 | C6: 1 | E6: Hide
A7: 3 | B7: 项目管理 | C7: 1 | E7: Hide
A8: 4 | B8: 临床监查 | C8: 1 | E8: Hide
A9: 5 | B9: 数据管理 | C9: 1 | E9: Hide
A10: 6 | B10: 生物统计 | C10: 1 | E10: Hide
A11: 7 | B11: 统计分析 | C11: 1 | E11: Hide
A12: 8 | B12: 临床药理 | C12: 1 | E12: Hide
A13: 9 | B13: 药物警戒 | C13: 1 | E13: Hide
A14: 10 | B14: 质量保证 | C14: 0 | E14: Hide
A15: 11 | B15: 注册事务 | C15: 0 | E15: Hide
A17: 项目参数
A18: 类别 | B18: 参数 | C18: 参数值 | D18: 备注
A19: 项目概要 | B19: 项目类型 | E19: Hide
A20: 项目概要 | B20: 治疗领域 | E20: Hide
A21: 项目概要 | B21: 适应症
A22: 项目概要 | B22: 试验目的 | C22: 注册申报 | D22: ="试验分期:"&E22 -> 试验分期:Ia | E22: Ia
A23: 项目概要 | B23: 遗传办递交和跟进 | C23: 适用
A24: 项目概要 | B24: 数据收集的语言 | C24: 中文
A25: 项目概要 | B25: 试验地点 | C25: 国内试验
A26: 项目概要 | B26: 试验参与者类型 | C26: 肿瘤患者
A27: 项目信息 | B27: 调研中心数 | C27: =IF(启动中心数<=10,ROUNDUP(启动中心数*200%,0),ROUNDUP(启动中心数*150%,0)) -> 8 | D27: 默认电话调研 | F27: 默认10个中心以内，200%;10个以上,150%; 预算敏感,可合理下调。
A28: 项目信息 | B28: 筛选中心数 | C28: =ROUNDUP(启动中心数*130%,0) -> 6 | F28: 默认10个中心以内，130%;10个以上,120%; 预算敏感,可合理下调。
A29: 项目信息 | B29: 启动中心数 | C29: 4
A30: 项目信息 | B30: 筛选试验参与者数 | C30: {=ROUND(入组试验参与者数/(1-D30),0)} -> 38 | D30: 0.2 | F30: 健康人50%-70%, 其他20%,罕见靶点/入排难可提高
A31: 项目信息 | B31: 入组试验参与者数 | C31: 30 | K31: 服务周期大于24mths时,请勾选Y
A32: 项目信息 | B32: 完成试验参与者数 | C32: {=ROUND(入组试验参与者数*(1-D32),0)} -> 24 | D32: 0.2 | E32: Hide
A33: 项目信息 | B33: 平均入组率 | C33: {=IFERROR(ROUND(入组试验参与者数/启动中心数/入组月,2),0)} -> 1.25 | D33: 每月每中心 | E33: Hide | H33: 通胀系数 | J33: 添加通胀 | K33: N | L33: =IF(K33="Y",L48,1) -> 1
A34: 项目信息 | B34: SAE 发生率 | C34: 0.3 | F34: 肿瘤SAE发生率按30%发生率计算； 心血管15%-25%；其他非健康人：10%；健康人：1%-5%
A35: 项目信息 | B35: SAE 例数 | C35: {=ROUNDUP(入组试验参与者数*SAE发生率,0)} -> 9 | E35: 编程
A36: 项目信息 | B36: 招募试验参与者数 | C36: {=ROUNDUP(筛选试验参与者数*200%,0)} -> 76
A37: 项目信息 | B37: 试验周期(月) | C37: =IFERROR(ROUND(项目时间计划!G20,1),) -> 22.5 | D37: 时间计划包括客户的审批时间，如因客户审批回复不及时等原因，项目时间计划将相应调整。关键节点如遇春节，十一等法定节假日，项目时间计划将相应顺延。 | G37: 年 | H37: 月数 | I37: 月数占比 | J37: 通胀每年 | K37: 累计通胀 | L37: 平均通胀
A38: 项目信息 | B38: 项目开始时间 (年月日) | C38: =IFERROR(项目时间计划!$E$20,) -> 46082 | D38: 研究中心启动时间为预估，如因研究药品不能及时到位或其他非CRO直接原因导致的研究中心不能及时启动，项目时间计划将相应调整。 | F38: 注意开始时间是否合理 | G38: 45657 | H38: =IF(AND(YEAR($C$38)<=YEAR($G$38),YEAR($C$39)>=YEAR($G38)),DATEDIF($C$38,$G38,"M")+1,0) -> 0 | I38: =H38/$H$48 -> 0 | J38: 1 | K38: 1 | L38: =ROUND(I38*K38,4) -> 0
A39: 项目信息 | B39: 项目结束时间 (年月日) | C39: =IFERROR(项目时间计划!$F$20,) -> 46763.975 | G39: 46022 | H39: =IF(YEAR($C$39)=YEAR($G39),MONTH($C$39),IF(AND(YEAR($C$38)<=YEAR($G39),YEAR($C$39)>=YEAR($G39)),DATEDIF($C$38,$G39,"M")+1-$H$38,0)) -> 0 | I39: =H39/$H$48 -> 0 | J39: 1 | K39: =J38*J39 -> 1 | L39: =ROUND(I39*K39,4) -> 0
A40: 项目信息 | B40: 方案定稿(月) | C40: =方案定稿月 -> 0.5 | G40: 46387 | H40: =IF(YEAR($C$39)=YEAR($G40),MONTH($C$39),IF(AND(YEAR($C$38)<=YEAR($G40),YEAR($C$39)>=YEAR($G40)),DATEDIF($C$38,$G40,"M")+1-SUM($H$38:H39),0)) -> 10 | I40: =H40/$H$48 -> 0.43478261 | J40: 1.05 | K40: =K39*J40 -> 1.05 | L40: =ROUND(I40*K40,4) -> 0.4565
A41: 项目信息 | B41: 启动期(月) | C41: =首家伦理月+遗传办月+首家合同月+项目时间计划!$G$8 -> 3 | G41: 46752 | H41: =IF(YEAR($C$39)=YEAR($G41),MONTH($C$39),IF(AND(YEAR($C$38)<=YEAR($G41),YEAR($C$39)>=YEAR($G41)),DATEDIF($C$38,$G41,"M")+1-SUM($H$38:H40),0)) -> 12 | I41: =H41/$H$48 -> 0.52173913 | J41: 1.05 | K41: =K40*J41 -> 1.1025 | L41: =ROUND(I41*K41,4) -> 0.5752
...

Sheet 费用摘要
B1: 报价摘要 | H1: 不对外展示，内部说明
B2: 报价版本号: | H2: 报价模板版本 | I2: v4.22
B3: 报价有效期: | C3: 90天 | E3: 不适用，则不展示 | F3: 不适用，则不展示 | H3: 报价模板版本日期 | I3: 46255
B4: 编码 | C4: 业务描述 | D4: 费用 (RMB) | E4: 优惠率 | F4: 折扣后费用 (RMB) | G4: 备注
B5: 注册申报 | C5: Pre-IND&IND&NDA | D5: =注册申报明细!H120 -> 0 | E5: =IF(F5<>D5,1-ROUND(IFERROR(F5/D5,0),2),"NA") -> NA | F5: =注册申报明细!J120 -> 0 | G5: 详情请见《注册申报费用明细》 | H5: 注册申报业务描述可根据实际情况调整
B6: 临床阶段 | D6: =SUM(D7:D21) -> 3348842 | E6: =IF(F6<>D6,1-ROUND(IFERROR(F6/D6,0),2),"NA") -> NA | F6: =SUM(F7:F21) -> 3348842 | H6: 如无注册申报相关服务，则不展示
B7: I001 | C7: =INDEX(服务费明细!$C:$C,MATCH(费用摘要!$B7,服务费明细!$B:$B,0)) -> 研究文件撰写和审核 | D7: =INDEX(服务费明细!$AF:$AF,MATCH(费用摘要!$B7,服务费明细!$B:$B,0)) -> 163695 | E7: =IF(F7<>D7,1-ROUND(IFERROR(F7/D7,0),2),"NA") -> NA | F7: =INDEX(服务费明细!$AH:$AH,MATCH(费用摘要!$B7,服务费明细!$B:$B,0)) -> 163695
B8: I002 | C8: =INDEX(服务费明细!$C:$C,MATCH(费用摘要!$B8,服务费明细!$B:$B,0)) -> 试验准备 | D8: =INDEX(服务费明细!$AF:$AF,MATCH(费用摘要!$B8,服务费明细!$B:$B,0)) -> 204560 | E8: =IF(F8<>D8,1-ROUND(IFERROR(F8/D8,0),2),"NA") -> NA | F8: =INDEX(服务费明细!$AH:$AH,MATCH(费用摘要!$B8,服务费明细!$B:$B,0)) -> 204560
B9: I003 | C9: =INDEX(服务费明细!$C:$C,MATCH(费用摘要!$B9,服务费明细!$B:$B,0)) -> 遗传办递交和跟进 | D9: =INDEX(服务费明细!$AF:$AF,MATCH(费用摘要!$B9,服务费明细!$B:$B,0)) -> 33020 | E9: =IF(F9<>D9,1-ROUND(IFERROR(F9/D9,0),2),"NA") -> NA | F9: =INDEX(服务费明细!$AH:$AH,MATCH(费用摘要!$B9,服务费明细!$B:$B,0)) -> 33020
B10: I004 | C10: =INDEX(服务费明细!$C:$C,MATCH(费用摘要!$B10,服务费明细!$B:$B,0)) -> 召开研究者会议 | D10: =INDEX(服务费明细!$AF:$AF,MATCH(费用摘要!$B10,服务费明细!$B:$B,0)) -> 73330 | E10: =IF(F10<>D10,1-ROUND(IFERROR(F10/D10,0),2),"NA") -> NA | F10: =INDEX(服务费明细!$AH:$AH,MATCH(费用摘要!$B10,服务费明细!$B:$B,0)) -> 73330
B11: I005 | C11: =INDEX(服务费明细!$C:$C,MATCH(费用摘要!$B11,服务费明细!$B:$B,0)) -> 临床监查和中心管理 | D11: =INDEX(服务费明细!$AF:$AF,MATCH(费用摘要!$B11,服务费明细!$B:$B,0)) -> 971055 | E11: =IF(F11<>D11,1-ROUND(IFERROR(F11/D11,0),2),"NA") -> NA | F11: =INDEX(服务费明细!$AH:$AH,MATCH(费用摘要!$B11,服务费明细!$B:$B,0)) -> 971055
B12: I006 | C12: =INDEX(服务费明细!$C:$C,MATCH(费用摘要!$B12,服务费明细!$B:$B,0)) -> 项目管理 | D12: =INDEX(服务费明细!$AF:$AF,MATCH(费用摘要!$B12,服务费明细!$B:$B,0)) -> 782562.5 | E12: =IF(F12<>D12,1-ROUND(IFERROR(F12/D12,0),2),"NA") -> NA | F12: =INDEX(服务费明细!$AH:$AH,MATCH(费用摘要!$B12,服务费明细!$B:$B,0)) -> 782562.5
B13: I007 | C13: =INDEX(服务费明细!$C:$C,MATCH(费用摘要!$B13,服务费明细!$B:$B,0)) -> 医学监查 | D13: =INDEX(服务费明细!$AF:$AF,MATCH(费用摘要!$B13,服务费明细!$B:$B,0)) -> 285273 | E13: =IF(F13<>D13,1-ROUND(IFERROR(F13/D13,0),2),"NA") -> NA | F13: =INDEX(服务费明细!$AH:$AH,MATCH(费用摘要!$B13,服务费明细!$B:$B,0)) -> 285273
B14: I008 | C14: =INDEX(服务费明细!$C:$C,MATCH(费用摘要!$B14,服务费明细!$B:$B,0)) -> 数据管理 | D14: =INDEX(服务费明细!$AF:$AF,MATCH(费用摘要!$B14,服务费明细!$B:$B,0)) -> 204684 | E14: =IF(F14<>D14,1-ROUND(IFERROR(F14/D14,0),2),"NA") -> NA | F14: =INDEX(服务费明细!$AH:$AH,MATCH(费用摘要!$B14,服务费明细!$B:$B,0)) -> 204684
B15: I009 | C15: =INDEX(服务费明细!$C:$C,MATCH(费用摘要!$B15,服务费明细!$B:$B,0)) -> 生物统计及分析 | D15: =INDEX(服务费明细!$AF:$AF,MATCH(费用摘要!$B15,服务费明细!$B:$B,0)) -> 243762.5 | E15: =IF(F15<>D15,1-ROUND(IFERROR(F15/D15,0),2),"NA") -> NA | F15: =INDEX(服务费明细!$AH:$AH,MATCH(费用摘要!$B15,服务费明细!$B:$B,0)) -> 243762.5
B16: I010 | C16: =INDEX(服务费明细!$C:$C,MATCH(费用摘要!$B16,服务费明细!$B:$B,0)) -> 临床药理 | D16: =INDEX(服务费明细!$AF:$AF,MATCH(费用摘要!$B16,服务费明细!$B:$B,0)) -> 113740 | E16: =IF(F16<>D16,1-ROUND(IFERROR(F16/D16,0),2),"NA") -> NA | F16: =INDEX(服务费明细!$AH:$AH,MATCH(费用摘要!$B16,服务费明细!$B:$B,0)) -> 113740
B17: I011 | C17: =INDEX(服务费明细!$C:$C,MATCH(费用摘要!$B17,服务费明细!$B:$B,0)) -> 安全警戒 | D17: =INDEX(服务费明细!$AF:$AF,MATCH(费用摘要!$B17,服务费明细!$B:$B,0)) -> 171520 | E17: =IF(F17<>D17,1-ROUND(IFERROR(F17/D17,0),2),"NA") -> NA | F17: =INDEX(服务费明细!$AH:$AH,MATCH(费用摘要!$B17,服务费明细!$B:$B,0)) -> 171520
B18: I012 | C18: =INDEX(服务费明细!$C:$C,MATCH(费用摘要!$B18,服务费明细!$B:$B,0)) -> 医学撰写 | D18: =INDEX(服务费明细!$AF:$AF,MATCH(费用摘要!$B18,服务费明细!$B:$B,0)) -> 101640 | E18: =IF(F18<>D18,1-ROUND(IFERROR(F18/D18,0),2),"NA") -> NA | F18: =INDEX(服务费明细!$AH:$AH,MATCH(费用摘要!$B18,服务费明细!$B:$B,0)) -> 101640
... B20: I014 | C20: =INDEX(服务费明细!$C:$C,MATCH(费用摘要!$B20,服务费明细!$B:$B,0)) -> 质量保证 | D20: =INDEX(服务费明细!$AF:$AF,MATCH(费用摘要!$B20,服务费明细!$B:$B,0)) -> 0 | E20: =IF(F20<>D20,1-ROUND(IFERROR(F20/D20,0),2),"NA") -> NA | F20: =INDEX(服务费明细!$AH:$AH,MATCH(费用摘要!$B20,服务费明细!$B:$B,0)) -> 0
B21: I015 | C21: =INDEX(服务费明细!$C:$C,MATCH(费用摘要!$B21,服务费明细!$B:$B,0)) -> 国家局核查支持 | D21: =INDEX(服务费明细!$AF:$AF,MATCH(费用摘要!$B21,服务费明细!$B:$B,0)) -> 0 | E21: =IF(F21<>D21,1-ROUND(IFERROR(F21/D21,0),2),"NA") -> NA | F21: =INDEX(服务费明细!$AH:$AH,MATCH(费用摘要!$B21,服务费明细!$B:$B,0)) -> 0 | G21: 临床试验结束后, 据实结算。
B22: 税前 | C22: 服务费合计 | D22: =ROUND(SUM($D$7:$D$21,D5),2) -> 3348842 | F22: =ROUND(SUM(F$7:F$21,F5),2) -> 3348842
B23: 税率 | C23: =服务费明细!$C$252 -> 0.066 | D23: =D24-D22 -> 221023.57 | F23: =F24-F22 -> 221023.57 | H23: 不展示
B24: 税后 | C24: 服务费合计 | D24: =ROUND(D22*(1+$C$23),2) -> 3569865.6 | F24: =ROUND(F22*(1+$C$23),2) -> 3569865.6 | H24: 不展示
B25: 税前 | C25: 服务费折扣金额 | D25: =D22-F22 -> 0 | E25: 优惠率 | F25: =IFERROR(ROUND(($D$22-$F$22)/$D$22,2),0) -> 0 | G25: =IF($F$25>0,IF(LEN(1-$F$25)-LEN(INT(1-$F$25))-1=1,(1-$F$25)*10&"折",(1-$F$25)*100&"折"),) -> 0 | H25: 不展示
B26: 编码 | C26: 其他费用描述 | D26: 费用 (RMB) | E26: 优惠率 | F26: 折扣后费用 (RMB) | G26: 备注
B27: TM | C27: =INDEX(其他费用明细!$D:$D,MATCH(费用摘要!$B27,其他费用明细!$C:$C,0)) -> 有临系统 | D27: =INDEX(其他费用明细!$I:$I,MATCH(费用摘要!$B27,其他费用明细!$C:$C,0)) -> 0 | E27: 0 | F27: =IF(E27="",D27,D27*(1-E27)) -> 0 | G27: =IF($E$27>0,IF(LEN(1-$E$27)-LEN(INT(1-$E$27))-1=1,(1-$E$27)*10&"折",(1-$E$27)*100&"折"),) -> 0 | H27: TM折扣根据审批填写
B28: PTU | C28: =INDEX(其他费用明细!$D:$D,MATCH(费用摘要!$B28,其他费用明细!$C:$C,0)) -> CRO间接费用 | D28: =INDEX(其他费用明细!$I:$I,MATCH(费用摘要!$B28,其他费用明细!$C:$C,0)) -> 147550 | E28: NA | F28: =IF(E28="NA",D28,D28*(1-E28)) -> 147550
B29: PTM | C29: =INDEX(其他费用明细!$D:$D,MATCH(费用摘要!$B29,其他费用明细!$C:$C,0)) -> 会议相关费用 | D29: =INDEX(其他费用明细!$I:$I,MATCH(费用摘要!$B29,其他费用明细!$C:$C,0)) -> 0 | E29: NA | F29: =IF(E29="NA",D29,D29*(1-E29)) -> 0
B30: PTV | C30: =INDEX(其他费用明细!$D:$D,MATCH(费用摘要!$B30,其他费用明细!$C:$C,0)) -> 供应商费用 | D30: =INDEX(其他费用明细!$I:$I,MATCH(费用摘要!$B30,其他费用明细!$C:$C,0)) -> 0 | E30: NA | F30: =IF(E30="NA",D30,D30*(1-E30)) -> 0
B31: PTS | C31: =INDEX(其他费用明细!$D:$D,MATCH(费用摘要!$B31,其他费用明细!$C:$C,0)) -> 研究中心费用 | D31: =INDEX(其他费用明细!$I:$I,MATCH(费用摘要!$B31,其他费用明细!$C:$C,0)) -> 0 | E31: NA | F31: =IF(E31="NA",D31,D31*(1-E31)) -> 0
B32: 税前 | C32: 其他费用合计 | D32: =ROUND(SUM($D$27:$D$31),2) -> 147550 | F32: =ROUND(SUM($F$27:$F$31),2) -> 147550 | G32: 据实结算
B33: 税率 | C33: =其他费用明细!D73 -> 0.066 | D33: =D34-D32 -> 9738.3 | F33: =F34-F32 -> 9738.3 | H33: 不展示
B34: 税后 | C34: 其他费用合计 | D34: =ROUND(D32*(1+$C$33),2) -> 157288.3 | F34: =ROUND(F32*(1+$C$33),2) -> 157288.3 | H34: 不展示
B36: 税前 | C36: 总计 | D36: =D22+D32 -> 3496392 | F36: =F22+F32 -> 3496392
B37: 税率 | C37: =服务费明细!C252 -> 0.066 | D37: =D38-D36 -> 230761.87 | F37: =F38-F36 -> 230761.87
B38: 税后 | C38: 总计 | D38: =D24+D34 -> 3727153.9 | F38: =F24+F34 -> 3727153.9 | H38: =F38/入组试验参与者数 -> 124238.46
B40: 已优惠总金额 | D40: =D38-F38 -> 0 | H40: 不展示
B41: 说明： | H41: 说明视情况调整 | I41: 2. 在入组病例数和中心数未发生变化，且项目周期延后不超过3个月的前提下，非有临直接原因导致的以下变更，将按以下原则收费:
B42: ﹡客户需在临床研究开始前根据项目需求，将相关定稿的核心文件提供给有临。 | I42: 1) 试验设计未发生实质性变更的前提下，文件定稿前如需额外版本，则每版按此项原服务费的5%收取；
B43: ﹡ 本报价均根据目前的信息估算，在一些影响因素发生变化时，相关费用也会发生变化，例如服务范围，研究设计，样本量，研究中心，研究时间等。如果相关信息发生变化时，有临会及时重新调整报价，并和客户进行沟通。 | I43: 2) 试验设计未发生实质性变更的前提下，文件定稿后发生修订，则每增加一次定稿版的修订按此项原服务费的25%收取；
...

Sheet Ballpark报价单

Sheet 服务费明细
B1: 服务费明细 | AI1: 备注需要根据实际情况修订，修订后本提示语删除！！ | AJ1: 仅供内部参考，外发须申请。 | BI1: 仅供内部参考，外发须申请。 | BQ1: 折扣前内部参考，不可外发。
B2: 注：是否执行,"0"表述CRO不执行且报价不含此服务，"1"表示CRO执行并报价。 | G2: 每个Task总工时。默认不展示,展示需王总审批并提示语删除 | AC2: 默认不展示 | AG2: 默认不展示,展示则提示语删除 | AH2: 默认不展示,展示则提示语删除
A3: 筛选 | B3: 编码 | C3: 专业服务 | D3: 是否执行 | E3: 数量 | F3: 单位类型 | G3: CRA | H3: CTA | I3: PM | J3: PMD | K3: QCM | L3: MD | M3: MM | N3: PVS | O3: PVM | P3: PVP | Q3: DBP | R3: DM | S3: LDM | T3: SA | U3: SAM | V3: ST | W3: STM | X3: CPS | Y3: CPSS | Z3: QAD | AA3: QAM | AB3: QAS | AC3: 小计 (RMB,不含税) | AD3: 逻辑检查 | AE3: 单价 (RMB,不含税) | AF3: 小计 (RMB,不含税) | AG3: 折扣后单价 (RMB,不含税) | AH3: 折扣后小计 (RMB,不含税) | AI3: 备注 | AJ3: 单位小时数 | AK3: 小时数 | AL3: CRA | AM3: CTA | AN3: PM | AO3: PMD | AP3: QCM | AQ3: MD | AR3: MM | AS3: PVS | AT3: PVM | AU3: PVP | AV3: DBP | AW3: DM | AX3: LDM | AY3: SA | AZ3: SAM | BA3: ST | BB3: STM | BC3: CPS | BD3: CPSS | BE3: QAD | BF3: QAM | BG3: QAS | BI3: 医学 | BJ3: 临床运营 | BK3: 数据管理 | BL3: 生物统计及分析 | BM3: 药物警戒 | BN3: 临床药理 | BO3: 质量保证 | BQ3: 医学 | BR3: 临床运营 | BS3: 数据管理 | BT3: 生物统计及分析 | BU3: 药物警戒 | BV3: 临床药理 | BW3: 质量保证
C4: 人员单价 | G4: ='Rate Card'!K3 -> 340 | H4: ='Rate Card'!J4 -> 220 | I4: ='Rate Card'!J5 -> 650 | J4: ='Rate Card'!J6 -> 800 | K4: ='Rate Card'!J7 -> 600 | L4: ='Rate Card'!K10 -> 990 | M4: ='Rate Card'!K11 -> 650 | N4: ='Rate Card'!K14 -> 300 | O4: ='Rate Card'!K12 -> 500 | P4: ='Rate Card'!K13 -> 700 | Q4: ='Rate Card'!K15 -> 300 | R4: ='Rate Card'!K16 -> 200 | S4: ='Rate Card'!K17 -> 360 | T4: ='Rate Card'!K18 -> 225 | U4: ='Rate Card'!K19 -> 450 | V4: ='Rate Card'!K20 -> 400 | W4: ='Rate Card'!K21 -> 700 | X4: ='Rate Card'!K25 -> 580 | Y4: ='Rate Card'!K26 -> 700 | Z4: ='Rate Card'!K22 -> 1000 | AA4: ='Rate Card'!K23 -> 600 | AB4: ='Rate Card'!K24 -> 400
B5: I001 | C5: =INDEX(二三级标准!$Q:$Q,MATCH(服务费明细!$B5,二三级标准!$O:$O,0)) -> 研究文件撰写和审核 | D5: =IF(医学撰写YN=1,1,0) -> 1 | G5: =SUM(G6:G14) -> 0 | H5: =SUM(H6:H14) -> 0 | I5: =SUM(I6:I14) -> 16 | J5: =SUM(J6:J14) -> 0 | K5: =SUM(K6:K14) -> 0 | L5: =SUM(L6:L14) -> 41.5 | M5: =SUM(M6:M14) -> 149 | N5: =SUM(N6:N14) -> 0 | ... AB5: =SUM(AB6:AB14) -> 0 | AD5: =SUM(G5:AB5) -> 247.5 | AF5: =SUM(AF6:AF14) -> 163695 | AH5: =SUM(AH6:AH14) -> 163695 | AK5: =SUM(AK6:AK14) -> 247.5 | BI5: =SUM(BI6:BI14) -> 190.5 | BJ5: =SUM(BJ6:BJ14) -> 16 | BK5: =SUM(BK6:BK14) -> 25 | BL5: =SUM(BL6:BL14) -> 12 | BM5: =SUM(BM6:BM14) -> 0 | BN5: =SUM(BN6:BN14) -> 4 | BO5: =SUM(BO6:BO14) -> 0 | BQ5: =SUM(BQ6:BQ14) -> 137935 | BR5: =SUM(BR6:BR14) -> 10400 | BS5: =SUM(BS6:BS14) -> 5960 | BT5: =SUM(BT6:BT14) -> 6600 | BU5: =SUM(BU6:BU14) -> 0 | BV5: =SUM(BV6:BV14) -> 2800 | BW5: =SUM(BW6:BW14) -> 0
B6: A001 | C6: =INDEX(二三级标准!$C:$C,MATCH(服务费明细!$B6,二三级标准!$B:$B,0)) -> 方案撰写 | D6: =IF($D$5=1,1,0) -> 1 | E6: =IF($D6=1,1,0) -> 1 | F6: =INDEX(二三级标准!$G:$G,MATCH(服务费明细!$B6,二三级标准!$B:$B,0)) -> 份 | G6: =AL6 -> 0 | H6: =AM6 -> 0 | I6: =AN6 -> 0 | J6: =AO6 -> 0 | K6: =AP6 -> 0 | L6: =AQ6 -> 26 | M6: =AR6 -> 80 | N6: =AS6 -> 0 | ... AB6: =BG6 -> 0 | AC6: {=SUMPRODUCT(G6:AB6,$G$4:$AB$4)} -> 81940 | AD6: =IF(AF6=AC6,TRUE,FALSE) -> TRUE | AE6: =IFERROR(SUMIF(服务费底表!$K:$K,服务费明细!$B6,服务费底表!$AD:$AD)/E6,0) -> 81940 | AF6: =E6*AE6 -> 81940 | AG6: =IFERROR(SUMIF(服务费底表!$K:$K,服务费明细!$B6,服务费底表!$AG:$AG)/E6,0) -> 81940 | AH6: =AG6*E6 -> 81940 | AI6: 默认2份草稿，1份终稿。 | AJ6: =IF(D6=1,AK6/E6,0) -> 112 | AK6: =SUMIF(服务费底表!$K:$K,服务费明细!$B6,服务费底表!$AC:$AC) -> 112 | AL6: =SUMIFS(服务费底表!$AC:$AC,服务费底表!$K:$K,服务费明细!$B6,服务费底表!$T:$T,AL$3) -> 0 | AM6: =SUMIFS(服务费底表!$AC:$AC,服务费底表!$K:$K,服务费明细!$B6,服务费底表!$T:$T,AM$3) -> 0 | AN6: =SUMIFS(服务费底表!$AC:$AC,服务费底表!$K:$K,服务费明细!$B6,服务费底表!$T:$T,AN$3) -> 0 | AO6: =SUMIFS(服务费底表!$AC:$AC,服务费底表!$K:$K,服务费明细!$B6,服务费底表!$T:$T,AO$3) -> 0 | AP6: =SUMIFS(服务费底表!$AC:$AC,服务费底表!$K:$K,服务费明细!$B6,服务费底表!$T:$T,AP$3) -> 0 | AQ6: =SUMIFS(服务费底表!$AC:$AC,服务费底表!$K:$K,服务费明细!$B6,服务费底表!$T:$T,AQ$3) -> 26 | AR6: =SUMIFS(服务费底表!$AC:$AC,服务费底表!$K:$K,服务费明细!$B6,服务费底表!$T:$T,AR$3) -> 80 | AS6: =SUMIFS(服务费底表!$AC:$AC,服务费底表!$K:$K,服务费明细!$B6,服务费底表!$T:$T,AS$3) -> 0 | ... BG6: =SUMIFS(服务费底表!$AC:$AC,服务费底表!$K:$K,服务费明细!$B6,服务费底表!$T:$T,BG$3) -> 0 | BI6: =SUMIFS(服务费底表!$AC:$AC,服务费底表!$K:$K,服务费明细!$B6,服务费底表!$H:$H,服务费明细!BI$3) -> 106 | BJ6: =SUMIFS(服务费底表!$AC:$AC,服务费底表!$K:$K,服务费明细!$B6,服务费底表!$H:$H,服务费明细!BJ$3) -> 0 | BK6: =SUMIFS(服务费底表!$AC:$AC,服务费底表!$K:$K,服务费明细!$B6,服务费底表!$H:$H,服务费明细!BK$3) -> 0 | BL6: =SUMIFS(服务费底表!$AC:$AC,服务费底表!$K:$K,服务费明细!$B6,服务费底表!$H:$H,服务费明细!BL$3) -> 6 | BM6: =SUMIFS(服务费底表!$AC:$AC,服务费底表!$K:$K,服务费明细!$B6,服务费底表!$H:$H,服务费明细!BM$3) -> 0 | BN6: =SUMIFS(服务费底表!$AC:$AC,服务费底表!$K:$K,服务费明细!$B6,服务费底表!$H:$H,服务费明细!BN$3) -> 0 | BO6: =SUMIFS(服务费底表!$AC:$AC,服务费底表!$K:$K,服务费明细!$B6,服务费底表!$H:$H,服务费明细!BO$3) -> 0 | BQ6: =SUMIFS(服务费底表!$AD:$AD,服务费底表!$K:$K,服务费明细!$B6,服务费底表!$H:$H,服务费明细!BQ$3) -> 77740 | BR6: =SUMIFS(服务费底表!$AD:$AD,服务费底表!$K:$K,服务费明细!$B6,服务费底表!$H:$H,服务费明细!BR$3) -> 0 | BS6: =SUMIFS(服务费底表!$AD:$AD,服务费底表!$K:$K,服务费明细!$B6,服务费底表!$H:$H,服务费明细!BS$3) -> 0 | BT6: =SUMIFS(服务费底表!$AD:$AD,服务费底表!$K:$K,服务费明细!$B6,服务费底表!$H:$H,服务费明细!BT$3) -> 4200 | BU6: =SUMIFS(服务费底表!$AD:$AD,服务费底表!$K:$K,服务费明细!$B6,服务费底表!$H:$H,服务费明细!BU$3) -> 0 | BV6: =SUMIFS(服务费底表!$AD:$AD,服务费底表!$K:$K,服务费明细!$B6,服务费底表!$H:$H,服务费明细!BV$3) -> 0 | BW6: =SUMIFS(服务费底表!$AD:$AD,服务费底表!$K:$K,服务费明细!$B6,服务费底表!$H:$H,服务费明细!BW$3) -> 0
B7: A284 | C7: =INDEX(二三级标准!$C:$C,MATCH(服务费明细!$B7,二三级标准!$B:$B,0)) -> 熟悉与研究相关的资料及文献检索 | D7: 0 | E7: =IF($D7=1,1,0) -> 0 | F7: =INDEX(二三级标准!$G:$G,MATCH(服务费明细!$B7,二三级标准!$B:$B,0)) -> 项目 | AE7: =IFERROR(SUMIF(服务费底表!$K:$K,服务费明细!$B7,服务费底表!$AD:$AD)/E7,0) -> 0 | AF7: =E7*AE7 -> 0 | AG7: =IFERROR(SUMIF(服务费底表!$K:$K,服务费明细!$B7,服务费底表!$AG:$AG)/E7,0) -> 0 | AH7: =AG7*E7 -> 0 | AJ7: =IF(D7=1,AK7/E7,0) -> 0 | AK7: =SUMIF(服务费底表!$K:$K,服务费明细!$B7,服务费底表!$AC:$AC) -> 0 | AL7: =SUMIFS(服务费底表!$AC:$AC,服务费底表!$K:$K,服务费明细!$B7,服务费底表!$T:$T,AL$3) -> 0 | AM7: =SUMIFS(服务费底表!$AC:$AC,服务费底表!$K:$K,服务费明细!$B7,服务费底表!$T:$T,AM$3) -> 0 | AN7: =SUMIFS(服务费底表!$AC:$AC,服务费底表!$K:$K,服务费明细!$B7,服务费底表!$T:$T,AN$3) -> 0 | AO7: =SUMIFS(服务费底表!$AC:$AC,服务费底表!$K:$K,服务费明细!$B7,服务费底表!$T:$T,AO$3) -> 0 | AP7: =SUMIFS(服务费底表!$AC:$AC,服务费底表!$K:$K,服务费明细!$B7,服务费底表!$T:$T,AP$3) -> 0 | AQ7: =SUMIFS(服务费底表!$AC:$AC,服务费底表!$K:$K,服务费明细!$B7,服务费底表!$T:$T,AQ$3) -> 0 | AR7: =SUMIFS(服务费底表!$AC:$AC,服务费底表!$K:$K,服务费明细!$B7,服务费底表!$T:$T,AR$3) -> 0 | AS7: =SUMIFS(服务费底表!$AC:$AC,服务费底表!$K:$K,服务费明细!$B7,服务费底表!$T:$T,AS$3) -> 0 | ... BG7: =SUMIFS(服务费底表!$AC:$AC,服务费底表!$K:$K,服务费明细!$B7,服务费底表!$T:$T,BG$3) -> 0
B8: A001a | C8: =INDEX(二三级标准!$C:$C,MATCH(服务费明细!$B8,二三级标准!$B:$B,0)) -> 方案（中译英） | D8: 0 | E8: =IF($D8=1,1,0) -> 0 | F8: =INDEX(二三级标准!$G:$G,MATCH(服务费明细!$B8,二三级标准!$B:$B,0)) -> 份 | G8: =AL8 -> 0 | H8: =AM8 -> 0 | I8: =AN8 -> 0 | J8: =AO8 -> 0 | K8: =AP8 -> 0 | L8: =AQ8 -> 0 | M8: =AR8 -> 0 | N8: =AS8 -> 0 | ... AB8: =BG8 -> 0 | AC8: {=SUMPRODUCT(G8:AB8,$G$4:$AB$4)} -> 0 | AD8: =IF(AF8=AC8,TRUE,FALSE) -> TRUE | AE8: =IFERROR(SUMIF(服务费底表!$K:$K,服务费明细!$B8,服务费底表!$AD:$AD)/E8,0) -> 0 | AF8: =E8*AE8 -> 0 | AG8: =IFERROR(SUMIF(服务费底表!$K:$K,服务费明细!$B8,服务费底表!$AG:$AG)/E8,0) -> 0 | AH8: =AG8*E8 -> 0 | AI8: 医学审阅 | AJ8: =IF(D8=1,AK8/E8,0) -> 0 | AK8: =SUMIF(服务费底表!$K:$K,服务费明细!$B8,服务费底表!$AC:$AC) -> 0 | AL8: =SUMIFS(服务费底表!$AC:$AC,服务费底表!$K:$K,服务费明细!$B8,服务费底表!$T:$T,AL$3) -> 0 | AM8: =SUMIFS(服务费底表!$AC:$AC,服务费底表!$K:$K,服务费明细!$B8,服务费底表!$T:$T,AM$3) -> 0 | AN8: =SUMIFS(服务费底表!$AC:$AC,服务费底表!$K:$K,服务费明细!$B8,服务费底表!$T:$T,AN$3) -> 0 | AO8: =SUMIFS(服务费底表!$AC:$AC,服务费底表!$K:$K,服务费明细!$B8,服务费底表!$T:$T,AO$3) -> 0 | AP8: =SUMIFS(服务费底表!$AC:$AC,服务费底表!$K:$K,服务费明细!$B8,服务费底表!$T:$T,AP$3) -> 0 | AQ8: =SUMIFS(服务费底表!$AC:$AC,服务费底表!$K:$K,服务费明细!$B8,服务费底表!$T:$T,AQ$3) -> 0 | AR8: =SUMIFS(服务费底表!$AC:$AC,服务费底表!$K:$K,服务费明细!$B8,服务费底表!$T:$T,AR$3) -> 0 | AS8: =SUMIFS(服务费底表!$AC:$AC,服务费底表!$K:$K,服务费明细!$B8,服务费底表!$T:$T,AS$3) -> 0 | ... BG8: =SUMIFS(服务费底表!$AC:$AC,服务费底表!$K:$K,服务费明细!$B8,服务费底表!$T:$T,BG$3) -> 0 | BI8: =SUMIFS(服务费底表!$AC:$AC,服务费底表!$K:$K,服务费明细!$B8,服务费底表!$H:$H,服务费明细!BI$3) -> 0 | BJ8: =SUMIFS(服务费底表!$AC:$AC,服务费底表!$K:$K,服务费明细!$B8,服务费底表!$H:$H,服务费明细!BJ$3) -> 0 | BK8: =SUMIFS(服务费底表!$AC:$AC,服务费底表!$K:$K,服务费明细!$B8,服务费底表!$H:$H,服务费明细!BK$3) -> 0 | BL8: =SUMIFS(服务费底表!$AC:$AC,服务费底表!$K:$K,服务费明细!$B8,服务费底表!$H:$H,服务费明细!BL$3) -> 0 | BM8: =SUMIFS(服务费底表!$AC:$AC,服务费底表!$K:$K,服务费明细!$B8,服务费底表!$H:$H,服务费明细!BM$3) -> 0 | BN8: =SUMIFS(服务费底表!$AC:$AC,服务费底表!$K:$K,服务费明细!$B8,服务费底表!$H:$H,服务费明细!BN$3) -> 0 | BO8: =SUMIFS(服务费底表!$AC:$AC,服务费底表!$K:$K,服务费明细!$B8,服务费底表!$H:$H,服务费明细!BO$3) -> 0 | BQ8: =SUMIFS(服务费底表!$AD:$AD,服务费底表!$K:$K,服务费明细!$B8,服务费底表!$H:$H,服务费明细!BQ$3) -> 0 | BR8: =SUMIFS(服务费底表!$AD:$AD,服务费底表!$K:$K,服务费明细!$B8,服务费底表!$H:$H,服务费明细!BR$3) -> 0 | BS8: =SUMIFS(服务费底表!$AD:$AD,服务费底表!$K:$K,服务费明细!$B8,服务费底表!$H:$H,服务费明细!BS$3) -> 0 | BT8: =SUMIFS(服务费底表!$AD:$AD,服务费底表!$K:$K,服务费明细!$B8,服务费底表!$H:$H,服务费明细!BT$3) -> 0 | BU8: =SUMIFS(服务费底表!$AD:$AD,服务费底表!$K:$K,服务费明细!$B8,服务费底表!$H:$H,服务费明细!BU$3) -> 0 | BV8: =SUMIFS(服务费底表!$AD:$AD,服务费底表!$K:$K,服务费明细!$B8,服务费底表!$H:$H,服务费明细!BV$3) -> 0 | BW8: =SUMIFS(服务费底表!$AD:$AD,服务费底表!$K:$K,服务费明细!$B8,服务费底表!$H:$H,服务费明细!BW$3) -> 0
B9: A002 | C9: =INDEX(二三级标准!$C:$C,MATCH(服务费明细!$B9,二三级标准!$B:$B,0)) -> 撰写CRF | D9: =IF($D$5=1,1,0) -> 1 | E9: =IF($D9=1,1,0) -> 1 | F9: =INDEX(二三级标准!$G:$G,MATCH(服务费明细!$B9,二三级标准!$B:$B,0)) -> 份 | G9: =AL9 -> 0 | H9: =AM9 -> 0 | I9: =AN9 -> 2 | J9: =AO9 -> 0 | K9: =AP9 -> 0 | L9: =AQ9 -> 0 | M9: =AR9 -> 8 | N9: =AS9 -> 0 | ... AB9: =BG9 -> 0 | AC9: {=SUMPRODUCT(G9:AB9,$G$4:$AB$4)} -> 13260 | AD9: =IF(AF9=AC9,TRUE,FALSE) -> TRUE | AE9: =IFERROR(SUMIF(服务费底表!$K:$K,服务费明细!$B9,服务费底表!$AD:$AD)/E9,0) -> 13260 | AF9: =E9*AE9 -> 13260 | AG9: =IFERROR(SUMIF(服务费底表!$K:$K,服务费明细!$B9,服务费底表!$AG:$AG)/E9,0) -> 13260 | AH9: =AG9*E9 -> 13260 | AI9: CRF页面设计。基于定稿的方案，提供1份定稿版本。 | AJ9: =IF(D9=1,AK9/E9,0) -> 37 | AK9: =SUMIF(服务费底表!$K:$K,服务费明细!$B9,服务费底表!$AC:$AC) -> 37 | AL9: =SUMIFS(服务费底表!$AC:$AC,服务费底表!$K:$K,服务费明细!$B9,服务费底表!$T:$T,AL$3) -> 0 | AM9: =SUMIFS(服务费底表!$AC:$AC,服务费底表!$K:$K,服务费明细!$B9,服务费底表!$T:$T,AM$3) -> 0 | AN9: =SUMIFS(服务费底表!$AC:$AC,服务费底表!$K:$K,服务费明细!$B9,服务费底表!$T:$T,AN$3) -> 2 | AO9: =SUMIFS(服务费底表!$AC:$AC,服务费底表!$K:$K,服务费明细!$B9,服务费底表!$T:$T,AO$3) -> 0 | AP9: =SUMIFS(服务费底表!$AC:$AC,服务费底表!$K:$K,服务费明细!$B9,服务费底表!$T:$T,AP$3) -> 0 | AQ9: =SUMIFS(服务费底表!$AC:$AC,服务费底表!$K:$K,服务费明细!$B9,服务费底表!$T:$T,AQ$3) -> 0 | AR9: =SUMIFS(服务费底表!$AC:$AC,服务费底表!$K:$K,服务费明细!$B9,服务费底表!$T:$T,AR$3) -> 8 | AS9: =SUMIFS(服务费底表!$AC:$AC,服务费底表!$K:$K,服务费明细!$B9,服务费底表!$T:$T,AS$3) -> 0 | ... BG9: =SUMIFS(服务费底表!$AC:$AC,服务费底表!$K:$K,服务费明细!$B9,服务费底表!$T:$T,BG$3) -> 0 | BI9: =SUMIFS(服务费底表!$AC:$AC,服务费底表!$K:$K,服务费明细!$B9,服务费底表!$H:$H,服务费明细!BI$3) -> 8 | BJ9: =SUMIFS(服务费底表!$AC:$AC,服务费底表!$K:$K,服务费明细!$B9,服务费底表!$H:$H,服务费明细!BJ$3) -> 2 | BK9: =SUMIFS(服务费底表!$AC:$AC,服务费底表!$K:$K,服务费明细!$B9,服务费底表!$H:$H,服务费明细!BK$3) -> 25 | BL9: =SUMIFS(服务费底表!$AC:$AC,服务费底表!$K:$K,服务费明细!$B9,服务费底表!$H:$H,服务费明细!BL$3) -> 2 | BM9: =SUMIFS(服务费底表!$AC:$AC,服务费底表!$K:$K,服务费明细!$B9,服务费底表!$H:$H,服务费明细!BM$3) -> 0 | BN9: =SUMIFS(服务费底表!$AC:$AC,服务费底表!$K:$K,服务费明细!$B9,服务费底表!$H:$H,服务费明细!BN$3) -> 0 | BO9: =SUMIFS(服务费底表!$AC:$AC,服务费底表!$K:$K,服务费明细!$B9,服务费底表!$H:$H,服务费明细!BO$3) -> 0 | BQ9: =SUMIFS(服务费底表!$AD:$AD,服务费底表!$K:$K,服务费明细!$B9,服务费底表!$H:$H,服务费明细!BQ$3) -> 5200 | BR9: =SUMIFS(服务费底表!$AD:$AD,服务费底表!$K:$K,服务费明细!$B9,服务费底表!$H:$H,服务费明细!BR$3) -> 1300 | BS9: =SUMIFS(服务费底表!$AD:$AD,服务费底表!$K:$K,服务费明细!$B9,服务费底表!$H:$H,服务费明细!BS$3) -> 5960 | BT9: =SUMIFS(服务费底表!$AD:$AD,服务费底表!$K:$K,服务费明细!$B9,服务费底表!$H:$H,服务费明细!BT$3) -> 800 | BU9: =SUMIFS(服务费底表!$AD:$AD,服务费底表!$K:$K,服务费明细!$B9,服务费底表!$H:$H,服务费明细!BU$3) -> 0 | BV9: =SUMIFS(服务费底表!$AD:$AD,服务费底表!$K:$K,服务费明细!$B9,服务费底表!$H:$H,服务费明细!BV$3) -> 0 | BW9: =SUMIFS(服务费底表!$AD:$AD,服务费底表!$K:$K,服务费明细!$B9,服务费底表!$H:$H,服务费明细!BW$3) -> 0
B10: A003 | C10: =INDEX(二三级标准!$C:$C,MATCH(服务费明细!$B10,二三级标准!$B:$B,0)) -> 方案版本更新 | D10: =IF($D$5=1,1,0) -> 1 | E10: =IF($D10=1,1,0) -> 1 | F10: =INDEX(二三级标准!$G:$G,MATCH(服务费明细!$B10,二三级标准!$B:$B,0)) -> 次 | G10: =AL10 -> 0 | H10: =AM10 -> 0 | I10: =AN10 -> 0 | J10: =AO10 -> 0 | K10: =AP10 -> 0 | L10: =AQ10 -> 10 | M10: =AR10 -> 42 | N10: =AS10 -> 0 | ... AB10: =BG10 -> 0 | AC10: {=SUMPRODUCT(G10:AB10,$G$4:$AB$4)} -> 41600 | AD10: =IF(AF10=AC10,TRUE,FALSE) -> TRUE | AE10: =IFERROR(SUMIF(服务费底表!$K:$K,服务费明细!$B10,服务费底表!$AD:$AD)/E10,0) -> 41600 | AF10: =E10*AE10 -> 41600 | AG10: =IFERROR(SUMIF(服务费底表!$K:$K,服务费明细!$B10,服务费底表!$AG:$AG)/E10,0) -> 41600 | AH10: =AG10*E10 -> 41600 | AI10: 基于定稿的方案，提供1份更新的定稿版本。 | AJ10: =IF(D10=1,AK10/E10,0) -> 60 | AK10: =SUMIF(服务费底表!$K:$K,服务费明细!$B10,服务费底表!$AC:$AC) -> 60 | AL10: =SUMIFS(服务费底表!$AC:$AC,服务费底表!$K:$K,服务费明细!$B10,服务费底表!$T:$T,AL$3) -> 0 | AM10: =SUMIFS(服务费底表!$AC:$AC,服务费底表!$K:$K,服务费明细!$B10,服务费底表!$T:$T,AM$3) -> 0 | AN10: =SUMIFS(服务费底表!$AC:$AC,服务费底表!$K:$K,服务费明细!$B10,服务费底表!$T:$T,AN$3) -> 0 | AO10: =SUMIFS(服务费底表!$AC:$AC,服务费底表!$K:$K,服务费明细!$B10,服务费底表!$T:$T,AO$3) -> 0 | AP10: =SUMIFS(服务费底表!$AC:$AC,服务费底表!$K:$K,服务费明细!$B10,服务费底表!$T:$T,AP$3) -> 0 | AQ10: =SUMIFS(服务费底表!$AC:$AC,服务费底表!$K:$K,服务费明细!$B10,服务费底表!$T:$T,AQ$3) -> 10 | AR10: =SUMIFS(服务费底表!$AC:$AC,服务费底表!$K:$K,服务费明细!$B10,服务费底表!$T:$T,AR$3) -> 42 | AS10: =SUMIFS(服务费底表!$AC:$AC,服务费底表!$K:$K,服务费明细!$B10,服务费底表!$T:$T,AS$3) -> 0 | ... BG10: =SUMIFS(服务费底表!$AC:$AC,服务费底表!$K:$K,服务费明细!$B10,服务费底表!$T:$T,BG$3) -> 0 | BI10: =SUMIFS(服务费底表!$AC:$AC,服务费底表!$K:$K,服务费明细!$B10,服务费底表!$H:$H,服务费明细!BI$3) -> 52 | BJ10: =SUMIFS(服务费底表!$AC:$AC,服务费底表!$K:$K,服务费明细!$B10,服务费底表!$H:$H,服务费明细!BJ$3) -> 0 | BK10: =SUMIFS(服务费底表!$AC:$AC,服务费底表!$K:$K,服务费明细!$B10,服务费底表!$H:$H,服务费明细!BK$3) -> 0 | BL10: =SUMIFS(服务费底表!$AC:$AC,服务费底表!$K:$K,服务费明细!$B10,服务费底表!$H:$H,服务费明细!BL$3) -> 4 | BM10: =SUMIFS(服务费底表!$AC:$AC,服务费底表!$K:$K,服务费明细!$B10,服务费底表!$H:$H,服务费明细!BM$3) -> 0 | BN10: =SUMIFS(服务费底表!$AC:$AC,服务费底表!$K:$K,服务费明细!$B10,服务费底表!$H:$H,服务费明细!BN$3) -> 4 | BO10: =SUMIFS(服务费底表!$AC:$AC,服务费底表!$K:$K,服务费明细!$B10,服务费底表!$H:$H,服务费明细!BO$3) -> 0 | BQ10: =SUMIFS(服务费底表!$AD:$AD,服务费底表!$K:$K,服务费明细!$B10,服务费底表!$H:$H,服务费明细!BQ$3) -> 37200 | BR10: =SUMIFS(服务费底表!$AD:$AD,服务费底表!$K:$K,服务费明细!$B10,服务费底表!$H:$H,服务费明细!BR$3) -> 0 | BS10: =SUMIFS(服务费底表!$AD:$AD,服务费底表!$K:$K,服务费明细!$B10,服务费底表!$H:$H,服务费明细!BS$3) -> 0 | BT10: =SUMIFS(服务费底表!$AD:$AD,服务费底表!$K:$K,服务费明细!$B10,服务费底表!$H:$H,服务费明细!BT$3) -> 1600 | BU10: =SUMIFS(服务费底表!$AD:$AD,服务费底表!$K:$K,服务费明细!$B10,服务费底表!$H:$H,服务费明细!BU$3) -> 0 | BV10: =SUMIFS(服务费底表!$AD:$AD,服务费底表!$K:$K,服务费明细!$B10,服务费底表!$H:$H,服务费明细!BV$3) -> 2800 | BW10: =SUMIFS(服务费底表!$AD:$AD,服务费底表!$K:$K,服务费明细!$B10,服务费底表!$H:$H,服务费明细!BW$3) -> 0
B11: A004 | C11: =INDEX(二三级标准!$C:$C,MATCH(服务费明细!$B11,二三级标准!$B:$B,0)) -> 主知情同意撰写 | D11: =IF($D$5=1,1,0) -> 1 | E11: =IF($D11=1,1,0) -> 1 | F11: =INDEX(二三级标准!$G:$G,MATCH(服务费明细!$B11,二三级标准!$B:$B,0)) -> 次 | G11: =AL11 -> 0 | H11: =AM11 -> 0 | I11: =AN11 -> 2 | J11: =AO11 -> 0 | K11: =AP11 -> 0 | L11: =AQ11 -> 4 | M11: =AR11 -> 10 | N11: =AS11 -> 0 | ... AB11: =BG11 -> 0 | AC11: {=SUMPRODUCT(G11:AB11,$G$4:$AB$4)} -> 11760 | AD11: =IF(AF11=AC11,TRUE,FALSE) -> TRUE | AE11: =IFERROR(SUMIF(服务费底表!$K:$K,服务费明细!$B11,服务费底表!$AD:$AD)/E11,0) -> 11760 | AF11: =E11*AE11 -> 11760 | AG11: =IFERROR(SUMIF(服务费底表!$K:$K,服务费明细!$B11,服务费底表!$AG:$AG)/E11,0) -> 11760 | AH11: =AG11*E11 -> 11760 | AI11: 基于定稿的方案，提供1份定稿版本。 | AJ11: =IF(D11=1,AK11/E11,0) -> 16 | AK11: =SUMIF(服务费底表!$K:$K,服务费明细!$B11,服务费底表!$AC:$AC) -> 16 | AL11: =SUMIFS(服务费底表!$AC:$AC,服务费底表!$K:$K,服务费明细!$B11,服务费底表!$T:$T,AL$3) -> 0 | AM11: =SUMIFS(服务费底表!$AC:$AC,服务费底表!$K:$K,服务费明细!$B11,服务费底表!$T:$T,AM$3) -> 0 | AN11: =SUMIFS(服务费底表!$AC:$AC,服务费底表!$K:$K,服务费明细!$B11,服务费底表!$T:$T,AN$3) -> 2 | AO11: =SUMIFS(服务费底表!$AC:$AC,服务费底表!$K:$K,服务费明细!$B11,服务费底表!$T:$T,AO$3) -> 0 | AP11: =SUMIFS(服务费底表!$AC:$AC,服务费底表!$K:$K,服务费明细!$B11,服务费底表!$T:$T,AP$3) -> 0 | AQ11: =SUMIFS(服务费底表!$AC:$AC,服务费底表!$K:$K,服务费明细!$B11,服务费底表!$T:$T,AQ$3) -> 4 | AR11: =SUMIFS(服务费底表!$AC:$AC,服务费底表!$K:$K,服务费明细!$B11,服务费底表!$T:$T,AR$3) -> 10 | AS11: =SUMIFS(服务费底表!$AC:$AC,服务费底表!$K:$K,服务费明细!$B11,服务费底表!$T:$T,AS$3) -> 0 | ... BG11: =SUMIFS(服务费底表!$AC:$AC,服务费底表!$K:$K,服务费明细!$B11,服务费底表!$T:$T,BG$3) -> 0 | BI11: =SUMIFS(服务费底表!$AC:$AC,服务费底表!$K:$K,服务费明细!$B11,服务费底表!$H:$H,服务费明细!BI$3) -> 14 | BJ11: =SUMIFS(服务费底表!$AC:$AC,服务费底表!$K:$K,服务费明细!$B11,服务费底表!$H:$H,服务费明细!BJ$3) -> 2 | BK11: =SUMIFS(服务费底表!$AC:$AC,服务费底表!$K:$K,服务费明细!$B11,服务费底表!$H:$H,服务费明细!BK$3) -> 0 | BL11: =SUMIFS(服务费底表!$AC:$AC,服务费底表!$K:$K,服务费明细!$B11,服务费底表!$H:$H,服务费明细!BL$3) -> 0 | BM11: =SUMIFS(服务费底表!$AC:$AC,服务费底表!$K:$K,服务费明细!$B11,服务费底表!$H:$H,服务费明细!BM$3) -> 0 | BN11: =SUMIFS(服务费底表!$AC:$AC,服务费底表!$K:$K,服务费明细!$B11,服务费底表!$H:$H,服务费明细!BN$3) -> 0 | BO11: =SUMIFS(服务费底表!$AC:$AC,服务费底表!$K:$K,服务费明细!$B11,服务费底表!$H:$H,服务费明细!BO$3) -> 0 | BQ11: =SUMIFS(服务费底表!$AD:$AD,服务费底表!$K:$K,服务费明细!$B11,服务费底表!$H:$H,服务费明细!BQ$3) -> 10460 | BR11: =SUMIFS(服务费底表!$AD:$AD,服务费底表!$K:$K,服务费明细!$B11,服务费底表!$H:$H,服务费明细!BR$3) -> 1300 | BS11: =SUMIFS(服务费底表!$AD:$AD,服务费底表!$K:$K,服务费明细!$B11,服务费底表!$H:$H,服务费明细!BS$3) -> 0 | BT11: =SUMIFS(服务费底表!$AD:$AD,服务费底表!$K:$K,服务费明细!$B11,服务费底表!$H:$H,服务费明细!BT$3) -> 0 | BU11: =SUMIFS(服务费底表!$AD:$AD,服务费底表!$K:$K,服务费明细!$B11,服务费底表!$H:$H,服务费明细!BU$3) -> 0 | BV11: =SUMIFS(服务费底表!$AD:$AD,服务费底表!$K:$K,服务费明细!$B11,服务费底表!$H:$H,服务费明细!BV$3) -> 0 | BW11: =SUMIFS(服务费底表!$AD:$AD,服务费底表!$K:$K,服务费明细!$B11,服务费底表!$H:$H,服务费明细!BW$3) -> 0
B12: A005 | C12: =INDEX(二三级标准!$C:$C,MATCH(服务费明细!$B12,二三级标准!$B:$B,0)) -> 主知情同意版本更新 | D12: =IF($D$5=1,1,0) -> 1 | E12: =IF($D12=1,1,0) -> 1 | F12: =INDEX(二三级标准!$G:$G,MATCH(服务费明细!$B12,二三级标准!$B:$B,0)) -> 份 | G12: =AL12 -> 0 | H12: =AM12 -> 0 | I12: =AN12 -> 0 | J12: =AO12 -> 0 | K12: =AP12 -> 0 | L12: =AQ12 -> 1.5 | M12: =AR12 -> 6 | N12: =AS12 -> 0 | ... AB12: =BG12 -> 0 | AC12: {=SUMPRODUCT(G12:AB12,$G$4:$AB$4)} -> 5385 | AD12: =IF(AF12=AC12,TRUE,FALSE) -> TRUE | AE12: =IFERROR(SUMIF(服务费底表!$K:$K,服务费明细!$B12,服务费底表!$AD:$AD)/E12,0) -> 5385 | AF12: =E12*AE12 -> 5385 | AG12: =IFERROR(SUMIF(服务费底表!$K:$K,服务费明细!$B12,服务费底表!$AG:$AG)/E12,0) -> 5385 | AH12: =AG12*E12 -> 5385 | AI12: 基于定稿的主知情，提供1份更新的定稿版本。 | AJ12: =IF(D12=1,AK12/E12,0) -> 7.5 | AK12: =SUMIF(服务费底表!$K:$K,服务费明细!$B12,服务费底表!$AC:$AC) -> 7.5 | AL12: =SUMIFS(服务费底表!$AC:$AC,服务费底表!$K:$K,服务费明细!$B12,服务费底表!$T:$T,AL$3) -> 0 | AM12: =SUMIFS(服务费底表!$AC:$AC,服务费底表!$K:$K,服务费明细!$B12,服务费底表!$T:$T,AM$3) -> 0 | AN12: =SUMIFS(服务费底表!$AC:$AC,服务费底表!$K:$K,服务费明细!$B12,服务费底表!$T:$T,AN$3) -> 0 | AO12: =SUMIFS(服务费底表!$AC:$AC,服务费底表!$K:$K,服务费明细!$B12,服务费底表!$T:$T,AO$3) -> 0 | AP12: =SUMIFS(服务费底表!$AC:$AC,服务费底表!$K:$K,服务费明细!$B12,服务费底表!$T:$T,AP$3) -> 0 | AQ12: =SUMIFS(服务费底表!$AC:$AC,服务费底表!$K:$K,服务费明细!$B12,服务费底表!$T:$T,AQ$3) -> 1.5 | AR12: =SUMIFS(服务费底表!$AC:$AC,服务费底表!$K:$K,服务费明细!$B12,服务费底表!$T:$T,AR$3) -> 6 | AS12: =SUMIFS(服务费底表!$AC:$AC,服务费底表!$K:$K,服务费明细!$B12,服务费底表!$T:$T,AS$3) -> 0 | ... BG12: =SUMIFS(服务费底表!$AC:$AC,服务费底表!$K:$K,服务费明细!$B12,服务费底表!$T:$T,BG$3) -> 0 | BI12: =SUMIFS(服务费底表!$AC:$AC,服务费底表!$K:$K,服务费明细!$B12,服务费底表!$H:$H,服务费明细!BI$3) -> 7.5 | BJ12: =SUMIFS(服务费底表!$AC:$AC,服务费底表!$K:$K,服务费明细!$B12,服务费底表!$H:$H,服务费明细!BJ$3) -> 0 | BK12: =SUMIFS(服务费底表!$AC:$AC,服务费底表!$K:$K,服务费明细!$B12,服务费底表!$H:$H,服务费明细!BK$3) -> 0 | BL12: =SUMIFS(服务费底表!$AC:$AC,服务费底表!$K:$K,服务费明细!$B12,服务费底表!$H:$H,服务费明细!BL$3) -> 0 | BM12: =SUMIFS(服务费底表!$AC:$AC,服务费底表!$K:$K,服务费明细!$B12,服务费底表!$H:$H,服务费明细!BM$3) -> 0 | BN12: =SUMIFS(服务费底表!$AC:$AC,服务费底表!$K:$K,服务费明细!$B12,服务费底表!$H:$H,服务费明细!BN$3) -> 0 | BO12: =SUMIFS(服务费底表!$AC:$AC,服务费底表!$K:$K,服务费明细!$B12,服务费底表!$H:$H,服务费明细!BO$3) -> 0 | BQ12: =SUMIFS(服务费底表!$AD:$AD,服务费底表!$K:$K,服务费明细!$B12,服务费底表!$H:$H,服务费明细!BQ$3) -> 5385 | BR12: =SUMIFS(服务费底表!$AD:$AD,服务费底表!$K:$K,服务费明细!$B12,服务费底表!$H:$H,服务费明细!BR$3) -> 0 | BS12: =SUMIFS(服务费底表!$AD:$AD,服务费底表!$K:$K,服务费明细!$B12,服务费底表!$H:$H,服务费明细!BS$3) -> 0 | BT12: =SUMIFS(服务费底表!$AD:$AD,服务费底表!$K:$K,服务费明细!$B12,服务费底表!$H:$H,服务费明细!BT$3) -> 0 | BU12: =SUMIFS(服务费底表!$AD:$AD,服务费底表!$K:$K,服务费明细!$B12,服务费底表!$H:$H,服务费明细!BU$3) -> 0 | BV12: =SUMIFS(服务费底表!$AD:$AD,服务费底表!$K:$K,服务费明细!$B12,服务费底表!$H:$H,服务费明细!BV$3) -> 0 | BW12: =SUMIFS(服务费底表!$AD:$AD,服务费底表!$K:$K,服务费明细!$B12,服务费底表!$H:$H,服务费明细!BW$3) -> 0
B13: A006 | C13: =INDEX(二三级标准!$C:$C,MATCH(服务费明细!$B13,二三级标准!$B:$B,0)) -> 试验参与者日记卡撰写 | D13: {=IF(AND($D$5=1,试验参与者类型<>"健康人"),1,0)} -> 1 | E13: =IF($D13=1,1,0) -> 1 | F13: =INDEX(二三级标准!$G:$G,MATCH(服务费明细!$B13,二三级标准!$B:$B,0)) -> 次 | G13: =AL13 -> 0 | H13: =AM13 -> 0 | I13: =AN13 -> 6 | J13: =AO13 -> 0 | K13: =AP13 -> 0 | L13: =AQ13 -> 0 | M13: =AR13 -> 2 | N13: =AS13 -> 0 | ... AB13: =BG13 -> 0 | AC13: {=SUMPRODUCT(G13:AB13,$G$4:$AB$4)} -> 5200 | AD13: =IF(AF13=AC13,TRUE,FALSE) -> TRUE | AE13: =IFERROR(SUMIF(服务费底表!$K:$K,服务费明细!$B13,服务费底表!$AD:$AD)/E13,0) -> 5200 | AF13: =E13*AE13 -> 5200 | AG13: =IFERROR(SUMIF(服务费底表!$K:$K,服务费明细!$B13,服务费底表!$AG:$AG)/E13,0) -> 5200 | AH13: =AG13*E13 -> 5200 | AI13: 基于定稿的方案，提供1份定稿版本。 | AJ13: =IF(D13=1,AK13/E13,0) -> 8 | AK13: =SUMIF(服务费底表!$K:$K,服务费明细!$B13,服务费底表!$AC:$AC) -> 8 | AL13: =SUMIFS(服务费底表!$AC:$AC,服务费底表!$K:$K,服务费明细!$B13,服务费底表!$T:$T,AL$3) -> 0 | AM13: =SUMIFS(服务费底表!$AC:$AC,服务费底表!$K:$K,服务费明细!$B13,服务费底表!$T:$T,AM$3) -> 0 | AN13: =SUMIFS(服务费底表!$AC:$AC,服务费底表!$K:$K,服务费明细!$B13,服务费底表!$T:$T,AN$3) -> 6 | AO13: =SUMIFS(服务费底表!$AC:$AC,服务费底表!$K:$K,服务费明细!$B13,服务费底表!$T:$T,AO$3) -> 0 | AP13: =SUMIFS(服务费底表!$AC:$AC,服务费底表!$K:$K,服务费明细!$B13,服务费底表!$T:$T,AP$3) -> 0 | AQ13: =SUMIFS(服务费底表!$AC:$AC,服务费底表!$K:$K,服务费明细!$B13,服务费底表!$T:$T,AQ$3) -> 0 | AR13: =SUMIFS(服务费底表!$AC:$AC,服务费底表!$K:$K,服务费明细!$B13,服务费底表!$T:$T,AR$3) -> 2 | AS13: =SUMIFS(服务费底表!$AC:$AC,服务费底表!$K:$K,服务费明细!$B13,服务费底表!$T:$T,AS$3) -> 0 | ... BG13: =SUMIFS(服务费底表!$AC:$AC,服务费底表!$K:$K,服务费明细!$B13,服务费底表!$T:$T,BG$3) -> 0 | BI13: =SUMIFS(服务费底表!$AC:$AC,服务费底表!$K:$K,服务费明细!$B13,服务费底表!$H:$H,服务费明细!BI$3) -> 2 | BJ13: =SUMIFS(服务费底表!$AC:$AC,服务费底表!$K:$K,服务费明细!$B13,服务费底表!$H:$H,服务费明细!BJ$3) -> 6 | BK13: =SUMIFS(服务费底表!$AC:$AC,服务费底表!$K:$K,服务费明细!$B13,服务费底表!$H:$H,服务费明细!BK$3) -> 0 | BL13: =SUMIFS(服务费底表!$AC:$AC,服务费底表!$K:$K,服务费明细!$B13,服务费底表!$H:$H,服务费明细!BL$3) -> 0 | BM13: =SUMIFS(服务费底表!$AC:$AC,服务费底表!$K:$K,服务费明细!$B13,服务费底表!$H:$H,服务费明细!BM$3) -> 0 | BN13: =SUMIFS(服务费底表!$AC:$AC,服务费底表!$K:$K,服务费明细!$B13,服务费底表!$H:$H,服务费明细!BN$3) -> 0 | BO13: =SUMIFS(服务费底表!$AC:$AC,服务费底表!$K:$K,服务费明细!$B13,服务费底表!$H:$H,服务费明细!BO$3) -> 0 | BQ13: =SUMIFS(服务费底表!$AD:$AD,服务费底表!$K:$K,服务费明细!$B13,服务费底表!$H:$H,服务费明细!BQ$3) -> 1300 | BR13: =SUMIFS(服务费底表!$AD:$AD,服务费底表!$K:$K,服务费明细!$B13,服务费底表!$H:$H,服务费明细!BR$3) -> 3900 | BS13: =SUMIFS(服务费底表!$AD:$AD,服务费底表!$K:$K,服务费明细!$B13,服务费底表!$H:$H,服务费明细!BS$3) -> 0 | BT13: =SUMIFS(服务费底表!$AD:$AD,服务费底表!$K:$K,服务费明细!$B13,服务费底表!$H:$H,服务费明细!BT$3) -> 0 | BU13: =SUMIFS(服务费底表!$AD:$AD,服务费底表!$K:$K,服务费明细!$B13,服务费底表!$H:$H,服务费明细!BU$3) -> 0 | BV13: =SUMIFS(服务费底表!$AD:$AD,服务费底表!$K:$K,服务费明细!$B13,服务费底表!$H:$H,服务费明细!BV$3) -> 0 | BW13: =SUMIFS(服务费底表!$AD:$AD,服务费底表!$K:$K,服务费明细!$B13,服务费底表!$H:$H,服务费明细!BW$3) -> 0
B14: A007 | C14: =INDEX(二三级标准!$C:$C,MATCH(服务费明细!$B14,二三级标准!$B:$B,0)) -> 试验参与者招募广告撰写 | D14: =IF($D$5=1,1,0) -> 1 | E14: =IF($D14=1,1,0) -> 1 | F14: =INDEX(二三级标准!$G:$G,MATCH(服务费明细!$B14,二三级标准!$B:$B,0)) -> 份 | G14: =AL14 -> 0 | H14: =AM14 -> 0 | I14: =AN14 -> 6 | J14: =AO14 -> 0 | K14: =AP14 -> 0 | L14: =AQ14 -> 0 | M14: =AR14 -> 1 | N14: =AS14 -> 0 | ... AB14: =BG14 -> 0 | AC14: {=SUMPRODUCT(G14:AB14,$G$4:$AB$4)} -> 4550 | AD14: =IF(AF14=AC14,TRUE,FALSE) -> TRUE | AE14: =IFERROR(SUMIF(服务费底表!$K:$K,服务费明细!$B14,服务费底表!$AD:$AD)/E14,0) -> 4550 | AF14: =E14*AE14 -> 4550 | AG14: =IFERROR(SUMIF(服务费底表!$K:$K,服务费明细!$B14,服务费底表!$AG:$AG)/E14,0) -> 4550 | AH14: =AG14*E14 -> 4550 | AI14: 基于定稿的方案，提供1份定稿版本。 | AJ14: =IF(D14=1,AK14/E14,0) -> 7 | AK14: =SUMIF(服务费底表!$K:$K,服务费明细!$B14,服务费底表!$AC:$AC) -> 7 | AL14: =SUMIFS(服务费底表!$AC:$AC,服务费底表!$K:$K,服务费明细!$B14,服务费底表!$T:$T,AL$3) -> 0 | AM14: =SUMIFS(服务费底表!$AC:$AC,服务费底表!$K:$K,服务费明细!$B14,服务费底表!$T:$T,AM$3) -> 0 | AN14: =SUMIFS(服务费底表!$AC:$AC,服务费底表!$K:$K,服务费明细!$B14,服务费底表!$T:$T,AN$3) -> 6 | AO14: =SUMIFS(服务费底表!$AC:$AC,服务费底表!$K:$K,服务费明细!$B14,服务费底表!$T:$T,AO$3) -> 0 | AP14: =SUMIFS(服务费底表!$AC:$AC,服务费底表!$K:$K,服务费明细!$B14,服务费底表!$T:$T,AP$3) -> 0 | AQ14: =SUMIFS(服务费底表!$AC:$AC,服务费底表!$K:$K,服务费明细!$B14,服务费底表!$T:$T,AQ$3) -> 0 | AR14: =SUMIFS(服务费底表!$AC:$AC,服务费底表!$K:$K,服务费明细!$B14,服务费底表!$T:$T,AR$3) -> 1 | AS14: =SUMIFS(服务费底表!$AC:$AC,服务费底表!$K:$K,服务费明细!$B14,服务费底表!$T:$T,AS$3) -> 0 | ... BG14: =SUMIFS(服务费底表!$AC:$AC,服务费底表!$K:$K,服务费明细!$B14,服务费底表!$T:$T,BG$3) -> 0 | BI14: =SUMIFS(服务费底表!$AC:$AC,服务费底表!$K:$K,服务费明细!$B14,服务费底表!$H:$H,服务费明细!BI$3) -> 1 | BJ14: =SUMIFS(服务费底表!$AC:$AC,服务费底表!$K:$K,服务费明细!$B14,服务费底表!$H:$H,服务费明细!BJ$3) -> 6 | BK14: =SUMIFS(服务费底表!$AC:$AC,服务费底表!$K:$K,服务费明细!$B14,服务费底表!$H:$H,服务费明细!BK$3) -> 0 | BL14: =SUMIFS(服务费底表!$AC:$AC,服务费底表!$K:$K,服务费明细!$B14,服务费底表!$H:$H,服务费明细!BL$3) -> 0 | BM14: =SUMIFS(服务费底表!$AC:$AC,服务费底表!$K:$K,服务费明细!$B14,服务费底表!$H:$H,服务费明细!BM$3) -> 0 | BN14: =SUMIFS(服务费底表!$AC:$AC,服务费底表!$K:$K,服务费明细!$B14,服务费底表!$H:$H,服务费明细!BN$3) -> 0 | BO14: =SUMIFS(服务费底表!$AC:$AC,服务费底表!$K:$K,服务费明细!$B14,服务费底表!$H:$H,服务费明细!BO$3) -> 0 | BQ14: =SUMIFS(服务费底表!$AD:$AD,服务费底表!$K:$K,服务费明细!$B14,服务费底表!$H:$H,服务费明细!BQ$3) -> 650 | BR14: =SUMIFS(服务费底表!$AD:$AD,服务费底表!$K:$K,服务费明细!$B14,服务费底表!$H:$H,服务费明细!BR$3) -> 3900 | BS14: =SUMIFS(服务费底表!$AD:$AD,服务费底表!$K:$K,服务费明细!$B14,服务费底表!$H:$H,服务费明细!BS$3) -> 0 | BT14: =SUMIFS(服务费底表!$AD:$AD,服务费底表!$K:$K,服务费明细!$B14,服务费底表!$H:$H,服务费明细!BT$3) -> 0 | BU14: =SUMIFS(服务费底表!$AD:$AD,服务费底表!$K:$K,服务费明细!$B14,服务费底表!$H:$H,服务费明细!BU$3) -> 0 | BV14: =SUMIFS(服务费底表!$AD:$AD,服务费底表!$K:$K,服务费明细!$B14,服务费底表!$H:$H,服务费明细!BV$3) -> 0 | BW14: =SUMIFS(服务费底表!$AD:$AD,服务费底表!$K:$K,服务费明细!$B14,服务费底表!$H:$H,服务费明细!BW$3) -> 0
B15: I002 | C15: =INDEX(二三级标准!$Q:$Q,MATCH(服务费明细!$B15,二三级标准!$O:$O,0)) -> 试验准备 | D15: =IF(临床监查YN=1,1,0) -> 1 | G15: =SUM(G17:G33) -> 295 | H15: =SUM(H17:H33) -> 43 | I15: =SUM(I17:I33) -> 64 | J15: =SUM(J17:J33) -> 2 | K15: =SUM(K17:K33) -> 0 | L15: =SUM(L17:L33) -> 1 | M15: =SUM(M17:M33) -> 61 | N15: =SUM(N17:N33) -> 0 | ... AB15: =SUM(AB17:AB33) -> 0 | AD15: =SUM(G15:AB15) -> 478 | AF15: =SUM(AF16:AF33) -> 204560 | AH15: =SUM(AH16:AH33) -> 204560 | AK15: =SUM(AK16:AK33) -> 486 | BI15: =SUM(BI17:BI33) -> 62 | BJ15: =SUM(BJ17:BJ33) -> 404 | BK15: =SUM(BK17:BK33) -> 3 | BL15: =SUM(BL17:BL33) -> 3 | BM15: =SUM(BM17:BM33) -> 3 | BN15: =SUM(BN17:BN33) -> 3 | BO15: =SUM(BO17:BO33) -> 0 | BQ15: =SUM(BQ17:BQ33) -> 40640 | BR15: =SUM(BR17:BR33) -> 152960 | BS15: =SUM(BS17:BS33) -> 1080 | BT15: =SUM(BT17:BT33) -> 1200 | BU15: =SUM(BU17:BU33) -> 1500 | BV15: =SUM(BV17:BV33) -> 1980 | BW15: =SUM(BW17:BW33) -> 0
B16: A286 | C16: =INDEX(二三级标准!$C:$C,MATCH(服务费明细!$B16,二三级标准!$B:$B,0)) -> 研究中心启动会/立项会资料支持 | D16: =IF($D$15=1,1,0) -> 1 | E16: =IF($D16=1,启动中心数,0) -> 4 | F16: =INDEX(二三级标准!$G:$G,MATCH(服务费明细!$B16,二三级标准!$B:$B,0)) -> 中心 | G16: =AL16 -> 0 | H16: =AM16 -> 0 | I16: =AN16 -> 0 | J16: =AO16 -> 0 | K16: =AP16 -> 0 | L16: =AQ16 -> 0 | M16: =AR16 -> 8 | N16: =AS16 -> 0 | ... AB16: =BG16 -> 0 | AC16: {=SUMPRODUCT(G16:AB16,$G$4:$AB$4)} -> 5200 | AD16: =IF(AF16=AC16,TRUE,FALSE) -> TRUE | AE16: =IFERROR(SUMIF(服务费底表!$K:$K,服务费明细!$B16,服务费底表!$AD:$AD)/E16,0) -> 1300 | AF16: =E16*AE16 -> 5200 | AG16: =IFERROR(SUMIF(服务费底表!$K:$K,服务费明细!$B16,服务费底表!$AG:$AG)/E16,0) -> 1300 | AH16: =AG16*E16 -> 5200 | AJ16: =IF(D16=1,AK16/E16,0) -> 2 | AK16: =SUMIF(服务费底表!$K:$K,服务费明细!$B16,服务费底表!$AC:$AC) -> 8 | AL16: =SUMIFS(服务费底表!$AC:$AC,服务费底表!$K:$K,服务费明细!$B16,服务费底表!$T:$T,AL$3) -> 0 | AM16: =SUMIFS(服务费底表!$AC:$AC,服务费底表!$K:$K,服务费明细!$B16,服务费底表!$T:$T,AM$3) -> 0 | AN16: =SUMIFS(服务费底表!$AC:$AC,服务费底表!$K:$K,服务费明细!$B16,服务费底表!$T:$T,AN$3) -> 0 | AO16: =SUMIFS(服务费底表!$AC:$AC,服务费底表!$K:$K,服务费明细!$B16,服务费底表!$T:$T,AO$3) -> 0 | AP16: =SUMIFS(服务费底表!$AC:$AC,服务费底表!$K:$K,服务费明细!$B16,服务费底表!$T:$T,AP$3) -> 0 | AQ16: =SUMIFS(服务费底表!$AC:$AC,服务费底表!$K:$K,服务费明细!$B16,服务费底表!$T:$T,AQ$3) -> 0 | AR16: =SUMIFS(服务费底表!$AC:$AC,服务费底表!$K:$K,服务费明细!$B16,服务费底表!$T:$T,AR$3) -> 8 | AS16: =SUMIFS(服务费底表!$AC:$AC,服务费底表!$K:$K,服务费明细!$B16,服务费底表!$T:$T,AS$3) -> 0 | ... BG16: =SUMIFS(服务费底表!$AC:$AC,服务费底表!$K:$K,服务费明细!$B16,服务费底表!$T:$T,BG$3) -> 0 | BI16: =SUMIFS(服务费底表!$AC:$AC,服务费底表!$K:$K,服务费明细!$B16,服务费底表!$H:$H,服务费明细!BI$3) -> 8 | BJ16: =SUMIFS(服务费底表!$AC:$AC,服务费底表!$K:$K,服务费明细!$B16,服务费底表!$H:$H,服务费明细!BJ$3) -> 0 | BK16: =SUMIFS(服务费底表!$AC:$AC,服务费底表!$K:$K,服务费明细!$B16,服务费底表!$H:$H,服务费明细!BK$3) -> 0 | BL16: =SUMIFS(服务费底表!$AC:$AC,服务费底表!$K:$K,服务费明细!$B16,服务费底表!$H:$H,服务费明细!BL$3) -> 0 | BM16: =SUMIFS(服务费底表!$AC:$AC,服务费底表!$K:$K,服务费明细!$B16,服务费底表!$H:$H,服务费明细!BM$3) -> 0 | BN16: =SUMIFS(服务费底表!$AC:$AC,服务费底表!$K:$K,服务费明细!$B16,服务费底表!$H:$H,服务费明细!BN$3) -> 0 | BO16: =SUMIFS(服务费底表!$AC:$AC,服务费底表!$K:$K,服务费明细!$B16,服务费底表!$H:$H,服务费明细!BO$3) -> 0 | BQ16: =SUMIFS(服务费底表!$AD:$AD,服务费底表!$K:$K,服务费明细!$B16,服务费底表!$H:$H,服务费明细!BQ$3) -> 5200 | BR16: =SUMIFS(服务费底表!$AD:$AD,服务费底表!$K:$K,服务费明细!$B16,服务费底表!$H:$H,服务费明细!BR$3) -> 0 | BS16: =SUMIFS(服务费底表!$AD:$AD,服务费底表!$K:$K,服务费明细!$B16,服务费底表!$H:$H,服务费明细!BS$3) -> 0 | BT16: =SUMIFS(服务费底表!$AD:$AD,服务费底表!$K:$K,服务费明细!$B16,服务费底表!$H:$H,服务费明细!BT$3) -> 0 | BU16: =SUMIFS(服务费底表!$AD:$AD,服务费底表!$K:$K,服务费明细!$B16,服务费底表!$H:$H,服务费明细!BU$3) -> 0 | BV16: =SUMIFS(服务费底表!$AD:$AD,服务费底表!$K:$K,服务费明细!$B16,服务费底表!$H:$H,服务费明细!BV$3) -> 0 | BW16: =SUMIFS(服务费底表!$AD:$AD,服务费底表!$K:$K,服务费明细!$B16,服务费底表!$H:$H,服务费明细!BW$3) -> 0
